Workbook

Sheet Resumen Empresa
A1: BRAIDY WONDERS SAC — Tesorería
A2: Ficha de la empresa y guía de uso del libro
A4: DATOS GENERALES (según Ficha RUC)
A5: Razón social | B5: BRAIDY WONDERS SAC
A6: RUC | B6: 20605765417
A7: Tipo de contribuyente | B7: Sociedad Anónima Cerrada (39)
A8: Estado / Condición | B8: ACTIVO / HABIDO
A9: Fecha de inicio de actividades | B9: 15/01/2020
A10: Emisor electrónico desde | B10: 01/07/2020 (Boleta), 20/08/2020 (Factura)
A11: Actividad económica principal | B11: 7911 - Actividades de agencias de viajes
A12: Actividad económica secundaria 1 | B12: 8690 - Otras actividades de atención de la salud humana
A13: Actividad económica secundaria 2 | B13: 5510 - Actividades de alojamiento para estancias cortas
A14: Comercio exterior | B14: Importador / Exportador
A15: Sistema de contabilidad | B15: Manual / Computarizado
A16: Régimen de renta (tributo afecto) | B16: Régimen MYPE Tributario (desde 01/01/2021)
... A18: Correo tesorería | B18: tesoreria@braidywonders.com
A20: TRIBUTOS REGISTRADOS (afectos)
A21: • | B21: IGV - Operaciones internas, cuenta propia (desde 15/01/2020)
A22: • | B22: Impuesto Temporal a los Activos Netos - ITAN (desde 01/03/2026)
A23: • | B23: Renta de 4ta categoría - Retenciones (desde 01/03/2021)
A24: • | B24: Renta de 5ta categoría - Retenciones (desde 01/09/2020)
A25: • | B25: Renta - Régimen MYPE Tributario (desde 01/01/2021)
A26: • | B26: ESSALUD - Seguro Regular del Trabajador (desde 01/09/2020)
A28: CÓMO USAR ESTE LIBRO
A29: 1. Guía Detracciones | B29: Reglas generales del sistema de detracciones (SPOT): montos mínimos, plazos de depósito, sanciones, liberación de fondos.
A30: 2. Categorías y Tasas | B30: Catálogo completo de bienes (Anexo 1 y 2) y servicios (Anexo 3) sujetos a detracción, con % y monto mínimo. Es la tabla base para clasificar cada factura.
A31: 3. Checklist Diario Facturas | B31: Hoja de trabajo: registra cada factura de proveedor recibida y el libro calcula automáticamente si aplica detracción, el % y el monto a depositar.
A32: 4. Plan de Cuentas PCGE | B32: Cuentas contables sugeridas (PCGE) para registrar compras, IGV y detracciones.
A33: 5. Asientos Tipo | B33: Ejemplos numéricos de asientos contables con y sin detracción, y del lado 'vendedor' (cuando Braidy Wonders emite comprobantes que también podrían estar sujetos).
A34: 6. Contexto Tributario | B34: Resumen de IGV, Régimen MYPE Tributario, cronograma de vencimientos y obligaciones formales relevantes para la empresa.
A36: Nota: esta guía es un apoyo de trabajo elaborado a partir de la normativa pública de SUNAT (R.S. N.° 183-2004/SUNAT y modificatorias) y fuentes especializadas. Para casos dudosos o de alto monto, valida el criterio con tu contador/asesor tributario antes de aplicar.

Sheet Guía Detracciones
A1: Sistema de Detracciones (SPOT) — Guía General
A2: Base legal: R.S. N.° 183-2004/SUNAT y modificatorias (D.Leg. 940)
A4: ¿Qué es? | B4: El adquirente/usuario de un bien o servicio 'detrae' (descuenta) un porcentaje del precio de venta y lo deposita en una cuenta del Banco de la Nación a nombre del PROVEEDOR. Esos fondos solo pueden usarse para pagar tributos, costas y gastos del proveedor; garantizan que SUNAT recaude el IGV de operaciones con alto riesgo de evasión.
A5: ¿Cuándo aplica (bienes Anexo 1)? | B5: Operaciones de venta gravadas con IGV por un importe MAYOR a 1/2 UIT (1/2 UIT 2026 = S/ 2,750, referencial; usar UIT vigente al momento de la operación). El depósito se hace ANTES del traslado del bien.
A6: ¿Cuándo aplica (bienes Anexo 2 y servicios Anexo 3)? | B6: Operaciones gravadas con IGV cuyo importe sea MAYOR a S/ 700 (igual o menor a S/ 700 → NO se detrae, salvo excepciones puntuales como transporte de carga con umbral de S/ 400).
A7: ¿Quién deposita y cuándo (servicios/bienes Anexo 2 y 3)? | B7: Regla general: el ADQUIRENTE deposita hasta la fecha de pago parcial o total al proveedor, o dentro del 5.° día hábil del mes siguiente a la anotación del comprobante en el Registro de Compras, lo que ocurra primero. Si el proveedor recibe el importe total sin que el adquirente haya depositado, el proveedor debe depositar dentro de los 5 días hábiles siguientes.
A8: Efecto sobre el crédito fiscal / costo o gasto | B8: Sin la constancia de depósito de la detracción, el comprador NO puede ejercer el crédito fiscal del IGV ni sustentar el costo o gasto para el Impuesto a la Renta de esa operación, hasta que regularice el depósito.
A9: Sanciones por incumplimiento | B9: • No depositar en el plazo: multa del 50% del monto no depositado (subsanable con rebaja). • Usar los fondos de la cuenta de detracciones en fines distintos a los permitidos: multa del 100% del importe indebidamente utilizado. • Trasladar bienes sin el depósito previo (Anexo 1): multa del 50% del monto no depositado.
A10: Liberación de fondos (para cuando Braidy Wonders es el proveedor detraído) | B10: Si los fondos de la cuenta de detracciones acumulan montos no agotados en el pago de tributos, se puede solicitar su liberación ante SUNAT hasta 4 veces al año (fechas fijas: primeros 5 días hábiles de enero, abril, julio y octubre), siempre que no exista deuda tributaria pendiente y se esté al día en PLE/registros exigidos. SUNAT resuelve y, de ser aprobada, el monto se puede cobrar en un plazo de 15 días hábiles desde la notificación.
A11: Código, número de cuenta y comprobante | B11: Cada depósito se hace por el Nº de RUC del proveedor, con el código del bien/servicio (Anexo 4), usando el Formulario Virtual 1662 (o vía SUNAT Virtual / banca por internet convenio con Banco de la Nación). El sistema genera una Constancia de Depósito que debe conservarse y referenciarse en el registro contable.
A12: Numeral 10 — 'Demás servicios gravados con el IGV' (código 037, 12%) | B12: Es una categoría 'residual': aplica a cualquier servicio gravado con IGV que no esté en otro numeral específico del Anexo 3 y que no sea alguna de las EXCLUSIONES expresas (p. ej.: servicios prestados por sujetos no domiciliados, laudos/espectáculos públicos, algunos servicios ya sujetos a otros regímenes). En la práctica, muchos servicios que recibe una agencia de viajes (guiado, coordinación, servicios operativos tercerizados, comisiones no clasificadas en otro numeral, etc.) terminan cayendo aquí. Ante la duda, verificar primero si encaja en un numeral específico (arrendamiento, mantenimiento, transporte, etc.); si no encaja y es un servicio gravado con IGV mayor a S/ 700, se aplica 12% por el numeral 10.

Sheet Categorías y Tasas
A1: Catálogo de Bienes y Servicios Sujetos a Detracción
A2: Anexos 1, 2 y 3 de la R.S. N.° 183-2004/SUNAT — tasas vigentes 2026
A4: Anexo | B4: Código | C4: Bien / Servicio | D4: Tasa | E4: Monto mínimo | F4: Cuenta PCGE sugerida (gasto/compra) | G4: Relevancia para Braidy Wonders (proveedores) | H4: Clave (uso interno - no borrar) | I4: Umbral S/ (numérico, uso interno)
A5: Anexo 1 | B5: 001 | C5: Azúcar y melaza de caña | D5: 0.1 | E5: > 1/2 UIT | F5: 60 Compras | G5: Baja | H5: 001 - Azúcar y melaza de caña | I5: 2750
A6: Anexo 1 | B6: 003 | C6: Alcohol etílico | D6: 0.1 | E6: > 1/2 UIT | F6: 60 Compras | G6: Baja | H6: 003 - Alcohol etílico | I6: 2750
A7: Anexo 2 | B7: 004 | C7: Recursos hidrobiológicos | D7: 0.04 | E7: S/ 700 | F7: 60 Compras | G7: Baja | H7: 004 - Recursos hidrobiológicos | I7: 700
A8: Anexo 2 | B8: 005 | C8: Maíz amarillo duro | D8: 0.04 | E8: S/ 700 | F8: 60 Compras | G8: Baja | H8: 005 - Maíz amarillo duro | I8: 700
A9: Anexo 2 | B9: 007 | C9: Caña de azúcar | D9: 0.1 | E9: S/ 700 | F9: 60 Compras | G9: Baja | H9: 007 - Caña de azúcar | I9: 700
A10: Anexo 2 | B10: 008 | C10: Madera | D10: 0.04 | E10: S/ 700 | F10: 60 Compras / 63 Serv. terceros | G10: Baja | H10: 008 - Madera | I10: 700
A11: Anexo 2 | B11: 009 | C11: Arena y piedra | D11: 0.1 | E11: S/ 700 | F11: 60 Compras | G11: Baja | H11: 009 - Arena y piedra | I11: 700
A12: Anexo 2 | B12: 010 | C12: Residuos, subproductos, desechos y chatarra | D12: 0.15 | E12: S/ 700 | F12: 60 Compras | G12: Baja | H12: 010 - Residuos, subproductos, desechos y chatarra | I12: 700
A13: Anexo 2 | B13: 011 | C13: Bienes gravados con IGV por renuncia a exoneración | D13: 0.1 | E13: S/ 700 | F13: 60 Compras | G13: Baja | H13: 011 - Bienes gravados con IGV por renuncia a exoneración | I13: 700
A14: Anexo 2 | B14: 014 | C14: Carnes y despojos comestibles | D14: 0.04 | E14: S/ 700 | F14: 60 Compras | G14: Media (servicio de salud/eventos) | H14: 014 - Carnes y despojos comestibles | I14: 700
A15: Anexo 2 | B15: 016 | C15: Aceite de pescado | D15: 0.1 | E15: S/ 700 | F15: 60 Compras | G15: Baja | H15: 016 - Aceite de pescado | I15: 700
A16: Anexo 2 | B16: 017 | C16: Harina, polvo y pellets de pescado | D16: 0.04 | E16: S/ 700 | F16: 60 Compras | G16: Baja | H16: 017 - Harina, polvo y pellets de pescado | I16: 700
... A36: No sujeto | B36: — | C36: Bien/servicio no listado en Anexos, o monto ≤ mínimo, o exonerado/inafecto de IGV | D36: 0 | E36: — | F36: 60/63/65 según naturaleza | G36: Confirmar en cada caso: boletas de venta a consumidor final, servicios de salud exonerados (Apéndice II), compras a NRUS, etc. | H36: — - Bien/servicio no listado en Anexos, o monto ≤ mínimo, o exon | I36: 0

Sheet Checklist Diario Facturas
A1: Checklist Diario — Facturas de Proveedores y Detracción
A2: Selecciona la categoría (col. F) y la hoja calcula automáticamente el % y el monto a depositar
A4: Fecha Factura | B4: Proveedor | C4: RUC Proveedor | D4: N° Comprobante | E4: Descripción del bien/servicio | F4: Categoría (elegir de la lista) | G4: Base imponible S/ (sin IGV) | H4: IGV 18% S/ | I4: Total factura S/ | J4: % Detracción (auto) | K4: Monto Detracción S/ (auto) | L4: Fecha límite depósito | M4: Cuenta PCGE gasto (auto) | N4: Estado depósito | O4: N° Constancia SUNAT | P4: Observaciones
A5: 2026-08-03 | B5: Consultores Legales Asociados SAC | C5: 20501234567 | D5: F001-2201 | E5: Asesoría legal por contrato de arrendamiento de local | F5: 022 - Otros servicios empresariales (legal, contable, consultoría, | G5: 1000 | H5: =IF(G5="","",ROUND(G5*0.18,2)) -> 180 | I5: =IF(G5="","",G5+H5) -> 1180 | J5: =IFERROR(INDEX('Categorías y Tasas'!$D$5:$D$36,MATCH(F5,'Categorías y Tasas'!$H$5:$H$36,0)),"") -> 0.12 | K5: =IF(OR(F5="",J5=""),"",IF(I5>IFERROR(INDEX('Categorías y Tasas'!$I$5:$I$36,MATCH(F5,'Categorías y Tasas'!$H$5:$H$36,0)),0),ROUND(I5*J5,2),0)) -> 141.6 | M5: =IFERROR(INDEX('Categorías y Tasas'!$F$5:$F$36,MATCH(F5,'Categorías y Tasas'!$H$5:$H$36,0)),"") -> 63 Gastos de servicios prestados por terceros | N5: Realizado | O5: 1662-000123456 | P5: Ejemplo ilustrativo
A6: 2026-08-05 | B6: Transportes del Sur EIRL | C6: 20601122334 | D6: F002-0087 | E6: Traslado terrestre de equipaje y mercadería (import.) | F6: 027 - Transporte de bienes por vía terrestre (carga) | G6: 850 | H6: =IF(G6="","",ROUND(G6*0.18,2)) -> 153 | I6: =IF(G6="","",G6+H6) -> 1003 | J6: =IFERROR(INDEX('Categorías y Tasas'!$D$5:$D$36,MATCH(F6,'Categorías y Tasas'!$H$5:$H$36,0)),"") -> 0.04 | K6: =IF(OR(F6="",J6=""),"",IF(I6>IFERROR(INDEX('Categorías y Tasas'!$I$5:$I$36,MATCH(F6,'Categorías y Tasas'!$H$5:$H$36,0)),0),ROUND(I6*J6,2),0)) -> 40.12 | M6: =IFERROR(INDEX('Categorías y Tasas'!$F$5:$F$36,MATCH(F6,'Categorías y Tasas'!$H$5:$H$36,0)),"") -> 63 Gastos de servicios prestados por terceros | N6: Pendiente | P6: Ejemplo ilustrativo
A7: 2026-08-06 | B7: Inmobiliaria Barranco SAC | C7: 20512345678 | D7: F010-0456 | E7: Alquiler mensual de oficina administrativa | F7: 019 - Arrendamiento de bienes muebles e inmuebles | G7: 3500 | H7: =IF(G7="","",ROUND(G7*0.18,2)) -> 630 | I7: =IF(G7="","",G7+H7) -> 4130 | J7: =IFERROR(INDEX('Categorías y Tasas'!$D$5:$D$36,MATCH(F7,'Categorías y Tasas'!$H$5:$H$36,0)),"") -> 0.1 | K7: =IF(OR(F7="",J7=""),"",IF(I7>IFERROR(INDEX('Categorías y Tasas'!$I$5:$I$36,MATCH(F7,'Categorías y Tasas'!$H$5:$H$36,0)),0),ROUND(I7*J7,2),0)) -> 413 | M7: =IFERROR(INDEX('Categorías y Tasas'!$F$5:$F$36,MATCH(F7,'Categorías y Tasas'!$H$5:$H$36,0)),"") -> 63 Gastos de servicios prestados por terceros | N7: Pendiente | P7: Ejemplo ilustrativo
H8: =IF(G8="","",ROUND(G8*0.18,2)) | I8: =IF(G8="","",G8+H8) | J8: =IFERROR(INDEX('Categorías y Tasas'!$D$5:$D$36,MATCH(F8,'Categorías y Tasas'!$H$5:$H$36,0)),"") | K8: =IF(OR(F8="",J8=""),"",IF(I8>IFERROR(INDEX('Categorías y Tasas'!$I$5:$I$36,MATCH(F8,'Categorías y Tasas'!$H$5:$H$36,0)),0),ROUND(I8*J8,2),0)) | M8: =IFERROR(INDEX('Categorías y Tasas'!$F$5:$F$36,MATCH(F8,'Categorías y Tasas'!$H$5:$H$36,0)),"")
H9: =IF(G9="","",ROUND(G9*0.18,2)) | I9: =IF(G9="","",G9+H9) | J9: =IFERROR(INDEX('Categorías y Tasas'!$D$5:$D$36,MATCH(F9,'Categorías y Tasas'!$H$5:$H$36,0)),"") | K9: =IF(OR(F9="",J9=""),"",IF(I9>IFERROR(INDEX('Categorías y Tasas'!$I$5:$I$36,MATCH(F9,'Categorías y Tasas'!$H$5:$H$36,0)),0),ROUND(I9*J9,2),0)) | M9: =IFERROR(INDEX('Categorías y Tasas'!$F$5:$F$36,MATCH(F9,'Categorías y Tasas'!$H$5:$H$36,0)),"")
H10: =IF(G10="","",ROUND(G10*0.18,2)) | I10: =IF(G10="","",G10+H10) | J10: =IFERROR(INDEX('Categorías y Tasas'!$D$5:$D$36,MATCH(F10,'Categorías y Tasas'!$H$5:$H$36,0)),"") | K10: =IF(OR(F10="",J10=""),"",IF(I10>IFERROR(INDEX('Categorías y Tasas'!$I$5:$I$36,MATCH(F10,'Categorías y Tasas'!$H$5:$H$36,0)),0),ROUND(I10*J10,2),0)) | M10: =IFERROR(INDEX('Categorías y Tasas'!$F$5:$F$36,MATCH(F10,'Categorías y Tasas'!$H$5:$H$36,0)),"")
H11: =IF(G11="","",ROUND(G11*0.18,2)) | I11: =IF(G11="","",G11+H11) | J11: =IFERROR(INDEX('Categorías y Tasas'!$D$5:$D$36,MATCH(F11,'Categorías y Tasas'!$H$5:$H$36,0)),"") | K11: =IF(OR(F11="",J11=""),"",IF(I11>IFERROR(INDEX('Categorías y Tasas'!$I$5:$I$36,MATCH(F11,'Categorías y Tasas'!$H$5:$H$36,0)),0),ROUND(I11*J11,2),0)) | M11: =IFERROR(INDEX('Categorías y Tasas'!$F$5:$F$36,MATCH(F11,'Categorías y Tasas'!$H$5:$H$36,0)),"")
H12: =IF(G12="","",ROUND(G12*0.18,2)) | I12: =IF(G12="","",G12+H12) | J12: =IFERROR(INDEX('Categorías y Tasas'!$D$5:$D$36,MATCH(F12,'Categorías y Tasas'!$H$5:$H$36,0)),"") | K12: =IF(OR(F12="",J12=""),"",IF(I12>IFERROR(INDEX('Categorías y Tasas'!$I$5:$I$36,MATCH(F12,'Categorías y Tasas'!$H$5:$H$36,0)),0),ROUND(I12*J12,2),0)) | M12: =IFERROR(INDEX('Categorías y Tasas'!$F$5:$F$36,MATCH(F12,'Categorías y Tasas'!$H$5:$H$36,0)),"")
H13: =IF(G13="","",ROUND(G13*0.18,2)) | I13: =IF(G13="","",G13+H13) | J13: =IFERROR(INDEX('Categorías y Tasas'!$D$5:$D$36,MATCH(F13,'Categorías y Tasas'!$H$5:$H$36,0)),"") | K13: =IF(OR(F13="",J13=""),"",IF(I13>IFERROR(INDEX('Categorías y Tasas'!$I$5:$I$36,MATCH(F13,'Categorías y Tasas'!$H$5:$H$36,0)),0),ROUND(I13*J13,2),0)) | M13: =IFERROR(INDEX('Categorías y Tasas'!$F$5:$F$36,MATCH(F13,'Categorías y Tasas'!$H$5:$H$36,0)),"")
H14: =IF(G14="","",ROUND(G14*0.18,2)) | I14: =IF(G14="","",G14+H14) | J14: =IFERROR(INDEX('Categorías y Tasas'!$D$5:$D$36,MATCH(F14,'Categorías y Tasas'!$H$5:$H$36,0)),"") | K14: =IF(OR(F14="",J14=""),"",IF(I14>IFERROR(INDEX('Categorías y Tasas'!$I$5:$I$36,MATCH(F14,'Categorías y Tasas'!$H$5:$H$36,0)),0),ROUND(I14*J14,2),0)) | M14: =IFERROR(INDEX('Categorías y Tasas'!$F$5:$F$36,MATCH(F14,'Categorías y Tasas'!$H$5:$H$36,0)),"")
H15: =IF(G15="","",ROUND(G15*0.18,2)) | I15: =IF(G15="","",G15+H15) | J15: =IFERROR(INDEX('Categorías y Tasas'!$D$5:$D$36,MATCH(F15,'Categorías y Tasas'!$H$5:$H$36,0)),"") | K15: =IF(OR(F15="",J15=""),"",IF(I15>IFERROR(INDEX('Categorías y Tasas'!$I$5:$I$36,MATCH(F15,'Categorías y Tasas'!$H$5:$H$36,0)),0),ROUND(I15*J15,2),0)) | M15: =IFERROR(INDEX('Categorías y Tasas'!$F$5:$F$36,MATCH(F15,'Categorías y Tasas'!$H$5:$H$36,0)),"")
H16: =IF(G16="","",ROUND(G16*0.18,2)) | I16: =IF(G16="","",G16+H16) | J16: =IFERROR(INDEX('Categorías y Tasas'!$D$5:$D$36,MATCH(F16,'Categorías y Tasas'!$H$5:$H$36,0)),"") | K16: =IF(OR(F16="",J16=""),"",IF(I16>IFERROR(INDEX('Categorías y Tasas'!$I$5:$I$36,MATCH(F16,'Categorías y Tasas'!$H$5:$H$36,0)),0),ROUND(I16*J16,2),0)) | M16: =IFERROR(INDEX('Categorías y Tasas'!$F$5:$F$36,MATCH(F16,'Categorías y Tasas'!$H$5:$H$36,0)),"")
H17: =IF(G17="","",ROUND(G17*0.18,2)) | I17: =IF(G17="","",G17+H17) | J17: =IFERROR(INDEX('Categorías y Tasas'!$D$5:$D$36,MATCH(F17,'Categorías y Tasas'!$H$5:$H$36,0)),"") | K17: =IF(OR(F17="",J17=""),"",IF(I17>IFERROR(INDEX('Categorías y Tasas'!$I$5:$I$36,MATCH(F17,'Categorías y Tasas'!$H$5:$H$36,0)),0),ROUND(I17*J17,2),0)) | M17: =IFERROR(INDEX('Categorías y Tasas'!$F$5:$F$36,MATCH(F17,'Categorías y Tasas'!$H$5:$H$36,0)),"")
H18: =IF(G18="","",ROUND(G18*0.18,2)) | I18: =IF(G18="","",G18+H18) | J18: =IFERROR(INDEX('Categorías y Tasas'!$D$5:$D$36,MATCH(F18,'Categorías y Tasas'!$H$5:$H$36,0)),"") | K18: =IF(OR(F18="",J18=""),"",IF(I18>IFERROR(INDEX('Categorías y Tasas'!$I$5:$I$36,MATCH(F18,'Categorías y Tasas'!$H$5:$H$36,0)),0),ROUND(I18*J18,2),0)) | M18: =IFERROR(INDEX('Categorías y Tasas'!$F$5:$F$36,MATCH(F18,'Categorías y Tasas'!$H$5:$H$36,0)),"")
H19: =IF(G19="","",ROUND(G19*0.18,2)) | I19: =IF(G19="","",G19+H19) | J19: =IFERROR(INDEX('Categorías y Tasas'!$D$5:$D$36,MATCH(F19,'Categorías y Tasas'!$H$5:$H$36,0)),"") | K19: =IF(OR(F19="",J19=""),"",IF(I19>IFERROR(INDEX('Categorías y Tasas'!$I$5:$I$36,MATCH(F19,'Categorías y Tasas'!$H$5:$H$36,0)),0),ROUND(I19*J19,2),0)) | M19: =IFERROR(INDEX('Categorías y Tasas'!$F$5:$F$36,MATCH(F19,'Categorías y Tasas'!$H$5:$H$36,0)),"")
... H64: =IF(G64="","",ROUND(G64*0.18,2)) | I64: =IF(G64="","",G64+H64) | J64: =IFERROR(INDEX('Categorías y Tasas'!$D$5:$D$36,MATCH(F64,'Categorías y Tasas'!$H$5:$H$36,0)),"") | K64: =IF(OR(F64="",J64=""),"",IF(I64>IFERROR(INDEX('Categorías y Tasas'!$I$5:$I$36,MATCH(F64,'Categorías y Tasas'!$H$5:$H$36,0)),0),ROUND(I64*J64,2),0)) | M64: =IFERROR(INDEX('Categorías y Tasas'!$F$5:$F$36,MATCH(F64,'Categorías y Tasas'!$H$5:$H$36,0)),"")
F66: TOTALES | G66: =SUM(G5:G64) -> 5350 | H66: =SUM(H5:H64) -> 963 | I66: =SUM(I5:I64) -> 6313 | K66: =SUM(K5:K64) -> 594.72
A68: Nota: la 'Fecha límite depósito' se calcula según la fecha de pago al proveedor (hasta ese día) o el 5.° día hábil del mes siguiente a la anotación en el Registro de Compras, lo que ocurra primero — regístrala manualmente en col. L según tu calendario de pagos.

Sheet Plan de Cuentas PCGE
A1: Plan Contable General Empresarial (PCGE) — Cuentas Clave
A2: Selección de cuentas relevantes para compras, IGV, detracciones y gastos de Braidy Wonders SAC
A4: Cuenta | B4: Denominación | C4: Uso en Braidy Wonders | D4: Naturaleza
A5: 10 | B5: Efectivo y equivalentes de efectivo | C5: Grupo de caja y bancos | D5: Activo
A6: 104 | B6: Cuentas corrientes en instituciones financieras | C6: Cuentas bancarias operativas de la empresa | D6: Activo
A7: 1041 | B7: Cuenta corriente operativa (banco principal) | C7: Pagos a proveedores, cobranzas de clientes | D7: Activo
A8: 1049* | B8: Cuenta de detracciones - Banco de la Nación (propia) | C8: Solo si Braidy Wonders EMITE comprobantes por servicios sujetos a detracción (ej. transporte de personas, comisiones); fondos de uso restringido recibidos de sus propios clientes | D8: Activo
A9: 12 | B9: Cuentas por cobrar comerciales - Terceros | C9: Facturas emitidas a clientes (paquetes turísticos, servicios) | D9: Activo
A10: 121 | B10: Facturas, boletas y otros comprobantes por cobrar | C10: Ventas al crédito a clientes | D10: Activo
A11: 20/21/23/24 | B11: Mercaderías / Productos terminados / Productos en proceso / Materias primas | C11: Solo aplica si Braidy Wonders compra/vende bienes tangibles (ej. insumos de salud, souvenirs) | D11: Activo
A12: 40 | B12: Tributos, contraprestaciones y aportes al sistema de pensiones y de salud por pagar | C12: Grupo de tributos por pagar/crédito fiscal | D12: Pasivo / Activo
A13: 4011 | B13: IGV - Cuenta propia | C13: Crédito fiscal de compras (débito) y débito fiscal de ventas (crédito) | D13: Activo/Pasivo según saldo
A14: 4017 | B14: Impuesto a la Renta de 3ra categoría (pagos a cuenta) | C14: Pagos a cuenta mensuales del Régimen MYPE Tributario | D14: Pasivo
A15: 403 | B15: Instituciones públicas (ESSALUD, ONP) | C15: Aportes de planilla del personal en relación de dependencia | D15: Pasivo
... A30: 94/95/79 | B30: Cuentas analíticas de gastos por función (si se usa contabilidad de costos) | C30: Distribución de gastos entre administrativos y de venta/operación (opcional, según política contable de la empresa) | D30: Analítica
A32: * Cuenta aplicable solo si Braidy Wonders es el PROVEEDOR de un servicio sujeto a detracción (lado ventas).

Sheet Asientos Tipo
A1: Asientos Contables Tipo — Compras con y sin Detracción
A2: Ejemplos numéricos bajo el método del PCGE (partida doble)
A4: CASO 1 — Servicio 'Otros servicios empresariales' (código 022, 12%) con detracción
A5: Ejemplo: Consultores Legales Asociados SAC factura S/ 1,000.00 + IGV 18% (S/ 180.00) = Total S/ 1,180.00. Detracción 12% sobre el total = S/ 141.60. Pago del neto al proveedor + depósito de la detracción en su cuenta del Banco de la Nación.
A6: Cuenta | B6: Denominación | C6: Debe (S/) | D6: Haber (S/)
B7: Por la factura recibida:
A8: 632 | B8: Asesoría y consultoría | C8: 1000
A9: 4011 | B9: IGV - Cuenta propia (crédito fiscal) | C9: 180
A10: 421 | B10: Facturas por pagar - Proveedor | D10: 1180
B11: Por el pago (neto + detracción):
A12: 421 | B12: Facturas por pagar - Proveedor | C12: 1180
A13: 1041 | B13: Cuenta corriente - pago neto al proveedor | D13: 1038.4
A14: 1041 | B14: Cuenta corriente - depósito detracción (cta. Bco. Nación del proveedor) | D14: 141.6
A16: CASO 2 — Arrendamiento de local (código 019, 10%) con detracción
A17: Ejemplo: Inmobiliaria Barranco SAC factura alquiler mensual S/ 3,500.00 + IGV 18% (S/ 630.00) = Total S/ 4,130.00. Detracción 10% sobre el total = S/ 413.00.
A18: Cuenta | B18: Denominación | C18: Debe (S/) | D18: Haber (S/)
B19: Por la factura recibida:
A20: 635 | B20: Alquileres | C20: 3500
A21: 4011 | B21: IGV - Cuenta propia (crédito fiscal) | C21: 630
A22: 421 | B22: Facturas por pagar - Proveedor | D22: 4130
B23: Por el pago (neto + detracción):
A24: 421 | B24: Facturas por pagar - Proveedor | C24: 4130
A25: 1041 | B25: Cuenta corriente - pago neto al proveedor | D25: 3717
A26: 1041 | B26: Cuenta corriente - depósito detracción (cta. Bco. Nación del proveedor) | D26: 413
A28: CASO 3 — Compra de suministros de oficina (NO sujeta a detracción)
A29: Ejemplo: Papelería y útiles S/ 300.00 + IGV 18% (S/ 54.00) = Total S/ 354.00. Monto menor al mínimo (S/ 700) y no está en ningún Anexo → no se detrae, se paga el 100% directamente al proveedor.
A30: Cuenta | B30: Denominación | C30: Debe (S/) | D30: Haber (S/)
A31: 65 | B31: Otros gastos de gestión (útiles de oficina) | C31: 300
A32: 4011 | B32: IGV - Cuenta propia (crédito fiscal) | C32: 54
A33: 421 | B33: Facturas por pagar - Proveedor | D33: 354
B34: Por el pago total:
A35: 421 | B35: Facturas por pagar - Proveedor | C35: 354
A36: 1041 | B36: Cuenta corriente - pago al proveedor | D36: 354
A38: CASO 4 (referencia a futuro) — Braidy Wonders EMITE un servicio sujeto a detracción
A39: Si Braidy Wonders factura, por ejemplo, transporte de personas (código 026, 10%) a un cliente que es agente retenedor de detracción, RECIBE el neto en su cuenta operativa y el 10% restante lo recibe en SU PROPIA cuenta de detracciones del Banco de la Nación (cuenta 1049), la cual solo puede usar para pagar sus propios tributos. Ejemplo: servicio de S/ 2,000.00 + IGV 18% (S/ 360.00) = Total S/ 2,360.00; detracción 10% = S/ 236.00.
A40: Cuenta | B40: Denominación | C40: Debe (S/) | D40: Haber (S/)
B41: Por la factura emitida:
A42: 121 | B42: Facturas por cobrar - Cliente | C42: 2360
A43: 70 | B43: Ventas (ingreso por servicios) | D43: 2000
A44: 4011 | B44: IGV - Cuenta propia (débito fiscal) | D44: 360
...

Sheet Contexto Tributario
A1: Contexto Tributario y Contable — Braidy Wonders SAC
A2: Régimen MYPE Tributario · IGV · Cronograma · Obligaciones formales
A4: Régimen de renta | B4: Régimen MYPE Tributario (RMT) desde 01/01/2021. Aplica mientras los ingresos netos anuales no superen 1,700 UIT (S/ 9,350,000 con UIT 2026 = S/ 5,500). Tasa: 10% sobre las primeras 15 UIT (S/ 82,500) de renta neta anual y 29.5% sobre el exceso.
A5: Pagos a cuenta mensuales | B5: 1% de los ingresos netos mensuales si los ingresos netos anuales no superan 300 UIT (S/ 1,650,000); si los superan, se aplica el coeficiente (ingresos del ejercicio anterior) o 1.5%, el que resulte mayor.
A6: IGV | B6: Tasa general 18% (16% IGV + 2% IPM), aplicable a la venta de servicios de agencia de viajes, alojamiento y, en general, a las operaciones gravadas de la empresa. Verificar caso por caso si algún servicio de salud calza en alguna exoneración del Apéndice II de la Ley del IGV.
A7: Comprobantes electrónicos | B7: Emisor electrónico desde 01/07/2020 (boleta) y 20/08/2020 (factura). Debe emitir comprobantes electrónicos vía SEE - SUNAT Operaciones en Línea o SEE - Sistema del Contribuyente, según corresponda, y llevar los Registros de Compras y Ventas de forma electrónica (PLE / SIRE).
A8: Retenciones de renta de 4ta y 5ta categoría | B8: Afecta desde 01/03/2021 (4ta) y 01/09/2020 (5ta): la empresa debe retener el Impuesto a la Renta a profesionales independientes (recibos por honorarios > S/ 1,500 aprox., según UIT vigente) y a sus trabajadores en planilla, y declararlas/pagarlas en el PDT PLAME.
A9: ESSALUD | B9: Aporte del 9% sobre la remuneración de los trabajadores en planilla (Seguro Regular), declarado y pagado junto con la PLAME.
A10: ITAN | B10: Impuesto Temporal a los Activos Netos, afecto desde 01/03/2026: aplica sobre activos netos que superen S/ 1,000,000, con tasas de 0% (hasta S/1MM) y 0.4% (exceso), pagadero en 9 cuotas o al contado; se puede usar como crédito contra los pagos a cuenta/regularización de renta.
A11: Cronograma de vencimientos 2026 | B11: Se determina según el último dígito del RUC (7 para Braidy Wonders). Las declaraciones mensuales (PDT 621 IGV-Renta) vencen entre el día 18 y 24 del mes siguiente (fechas exactas publicadas por SUNAT cada año; consultar el cronograma oficial vigente antes de cada vencimiento, ya que puede variar).
A12: Libros y registros electrónicos | B12: Al ser un régimen con sistema de contabilidad manual/computarizado y emisor electrónico, corresponde evaluar la obligación de llevar el Registro de Ventas e Ingresos y Registro de Compras a través del SIRE (Sistema Integrado de Registros Electrónicos), según el cronograma de incorporación de SUNAT.
A13: Comercio exterior (Importador/Exportador) | B13: Las importaciones de bienes están afectas al IGV en aduanas (además de derechos arancelarios); ese IGV pagado en aduanas también constituye crédito fiscal. Las exportaciones de servicios (si califican como tales bajo el Apéndice V de la Ley del IGV) están exoneradas/con derecho a saldo a favor del exportador — evaluar si algún servicio turístico prestado a no domiciliados califica.
A14: Actividades secundarias (salud y alojamiento) | B14: Si la empresa además presta servicios de salud humana (8690) o de alojamiento de estancias cortas (5510) de forma efectiva, revisar: (i) posibles exoneraciones de IGV para servicios de salud (Apéndice II), y (ii) el Impuesto de Promoción Municipal / arbitrios aplicables a establecimientos de hospedaje, que son distintos del sistema de detracciones.
A15: Representantes y accionistas (RUC) | B15: Gerente General: Elsa Leonor Peirano Ascurra (desde 16/08/2021). Apoderada: Verónica Elsa Napuri Peirano. Socios: Alister Stuart Wicks Napuri y Oliver Stuart Wicks Napuri (50% cada uno) — relevante para retenciones de dividendos (5% Impuesto a la Renta) cuando se acuerde distribución de utilidades.
A17: Próximos pasos sugeridos (fases 3 y 4 del proyecto): 1) usar la 'Checklist Diario Facturas' durante unas semanas para consolidar el universo real de proveedores y categorías de detracción de Braidy Wonders; 2) con ese historial, construir el detalle de asientos contables por tipo de operación (compras, ventas, planilla, activos fijos); 3) proyectar el Estado de Situación Financiera, Estado de Resultados y Flujo de Caja a partir de esos asientos y de los cronogramas de pago/cobro.
