Workbook
Name Catalogo_Codigos: Catalogo_Detracciones!$A$4:$A$15
Name Catalogo_Etiquetas: Catalogo_Detracciones!$C$4:$C$15
Name Catalogo_Tasas: Catalogo_Detracciones!$D$4:$D$15
Name Catalogo_Umbrales: Catalogo_Detracciones!$E$4:$E$15
Name Feriados: Detracciones_Control!$P$4:$P$60
Name TC_Fechas: TC_Diario!$A$4:$A$1003
Name TC_Venta_Rango: TC_Diario!$C$4:$C$1003

Sheet Instrucciones
A1: Libro Diario — Braidy Wonders SAC
A2: Plantilla de registro de facturas de compra y venta, con clasificación automática de detracción (SPOT) y generación automática de asientos PCGE.
A4: Cómo está armado este archivo
A5: • Registro_Compras: una fila por factura de proveedor recibida. Al elegir el "Concepto" (según el catálogo de detracción), el archivo calcula solas la tasa, si aplica detracción, el monto a depositar y el neto a pagar.
A6: • Registro_Ventas: una fila por comprobante emitido a un cliente. El caso normal es sin detracción (Braidy Wonders casi siempre es el adquiriente, no el prestador, del servicio sujeto a SPOT) — la columna "¿Sujeto a detracción emitida?" queda en "NO" salvo que el servicio que facturas sea uno de los del catálogo (ej. transporte de personas).
A7: • Catalogo_Detracciones: tabla de referencia (Anexo 3 + transporte de carga) de la que se alimentan los menús desplegables y las fórmulas de Registro_Compras/Registro_Ventas. No editar las columnas de tasa/umbral sin confirmar el cambio normativo primero.
A8: • Libro_Diario: se genera solo, a partir de Registro_Compras y Registro_Ventas — no se edita a mano. Cada factura de compra con detracción genera 4 asientos (provisión del gasto, destino del gasto, depósito de la detracción, pago del neto); una compra sin detracción genera 3 (se salta el depósito). Cada venta genera el asiento de devengo y, si marcas "¿Cobrado?" = SI, el asiento de cobranza.
A10: Qué llenar tú (celdas en azul / con relleno amarillo)
A11: En Registro_Compras y Registro_Ventas: todo excepto las columnas de fórmula (tienen fondo blanco normal, texto negro). Las columnas de fórmula no se tocan — se recalculan solas.
A12: La fila 4 de Registro_Compras y de Registro_Ventas es un EJEMPLO (fondo verde claro) tomado de la guía de detracciones — bórrala o sobrescríbela con tu primera factura real; ya está incluida en el conteo del Libro_Diario para que veas el resultado completo de un caso real antes de cargar los tuyos.
A14: Alcance y limitaciones de esta plantilla
A15: • Cubre el lado de compras con y sin detracción (fuente: guía de detracciones consolidada) y el lado de ventas en su forma estándar — el asiento de venta (Debe 12 / Haber 70 y 40111) es la mecánica contable general del PCGE, no vino desglosada con ejemplo numérico en las fuentes que subiste; revísala con tu contador antes de depender de ella para un cierre.
... A21: Ver hoja Plan_Cuentas — indica cuáles cuentas vienen confirmadas en las fuentes que subiste y cuáles son la aplicación estándar del PCGE para el lado de ventas (12, 70) que no estaba desarrollada en las fuentes.

Sheet Catalogo_Detracciones
A1: Catálogo de servicios sujetos a detracción (Anexo 3 SUNAT) — Braidy Wonders SAC
A2: Fuente: guía de detracciones consolidada (20.08.2026). No editar tasas/umbrales sin confirmar la norma vigente.
A3: Código SUNAT | B3: Servicio / Bien | C3: Etiqueta (para menú desplegable) | D3: Tasa | E3: Umbral (moneda de la op.) | F3: Rubro típico en Braidy Wonders
A4: 012 | B4: Intermediación laboral y tercerización | C4: 012 - Intermediación laboral y tercerización | D4: 0.12 | E4: 700 | F4: Limpieza/lavandería tercerizada (alojamiento)
A5: 019 | B5: Arrendamiento de bienes muebles e inmuebles | C5: 019 - Arrendamiento de bienes muebles e inmuebles | D5: 0.1 | E5: 700 | F5: Alquiler de locales, equipos
A6: 020 | B6: Mantenimiento y reparación de bienes muebles | C6: 020 - Mantenimiento y reparación de bienes muebles | D6: 0.12 | E6: 700 | F6: Mantenimiento de equipos (alojamiento)
A7: 021 | B7: Movimiento de carga | C7: 021 - Movimiento de carga | D7: 0.1 | E7: 700 | F7: Logística de equipaje/carga
A8: 022 | B8: Otros servicios empresariales (legal, contable, consultoría, publicidad) | C8: 022 - Otros servicios empresariales (legal, contable, consultoría, publicidad) | D8: 0.12 | E8: 700 | F8: Asesoría, consultoría, publicidad
A9: 024 | B9: Comisión mercantil | C9: 024 - Comisión mercantil | D9: 0.1 | E9: 700 | F9: Comisiones de sub-agentes / intermediarios turísticos
A10: 025 | B10: Fabricación de bienes por encargo | C10: 025 - Fabricacion de bienes por encargo | D10: 0.1 | E10: 700 | F10: Poco frecuente en el giro de Braidy Wonders
A11: 026 | B11: Servicio de transporte de personas | C11: 026 - Servicio de transporte de personas | D11: 0.1 | E11: 700 | F11: Transporte terrestre de pasajeros (paquetes turísticos)
A12: 027 | B12: Transporte de bienes por vía terrestre (carga) | C12: 027 - Transporte de bienes por vía terrestre (carga) | D12: 0.04 | E12: 400 | F12: Transporte de carga/equipaje
A13: 030 | B13: Contratos de construcción | C13: 030 - Contratos de construcción | D13: 0.04 | E13: 700 | F13: Remodelación/reparación inmobiliaria (alojamiento)
A14: 037 | B14: Demás servicios gravados con IGV (residual) | C14: 037 - Demás servicios gravados con IGV (residual) | D14: 0.12 | E14: 700 | F14: Hoteles/alojamiento local, salud gravada con IGV, servicios sin categoría propia
A15: N/A | B15: No sujeto a detracción (aéreo regular, salud exonerada de IGV, importación de bienes, etc.) | C15: N/A - No sujeto a detracción (aéreo regular, salud exonerada de IGV, importación de bienes, etc.) | D15: 0 | E15: 999999999 | F15: Boletos aéreos, servicios médicos exonerados, importaciones (aplica percepción, no SPOT)

Sheet Registro_Compras
A1: Registro de Compras - Facturas de Proveedores
A2: Llena solo las columnas de ENTRADA. Las columnas (auto) y de calculo se resuelven solas y no se tocan. La columna C (N° Comprobante) es el disparador: si esta vacia, la fila no genera ningun asiento.
A3: N° | B3: Fecha Emisión | C3: N° Comprobante | D3: RUC Proveedor | E3: Proveedor | F3: Tipo Comprobante | G3: Código SPOT | H3: Concepto (auto) | I3: Moneda | J3: Valor Venta | K3: IGV | L3: Total Comprobante | M3: Cuenta de Gasto (63x) | N3: TC (auto) | O3: Total PEN | P3: % Detracción | Q3: Umbral S/ | R3: Sujeto a Detracción | S3: Detracción S/ (calculada) | T3: Detracción S/ (comprobante) | U3: Validación Detracción | V3: Retención 4ta (moneda fact.) | W3: Neto a Pagar (moneda fact.) | X3: Fecha Depósito Detracción | Y3: Fecha Pago Neto | Z3: N° Constancia SUNAT | AA3: Estado | AB3: Tipo Gasto
A4: 1 | B4: 46253 | C4: F001-00005653 | D4: 20307167442 | E4: COMISION DE PROMOCION DEL PERU PARA LA EXPORTACION Y EL TURISMO - PROMPERU | F4: FACTURA | G4: 037 | H4: =IF($G4="","",IFERROR(INDEX(Catalogo_Etiquetas,MATCH($G4,Catalogo_Codigos,0)),"CODIGO NO VALIDO")) | I4: PEN | J4: 5094.92 | K4: 917.08 | L4: =IF($C4="","",$J4+$K4) | M4: 637 | N4: =IF($C4="","",IF($I4="PEN",1,IFERROR(IF(_xlfn.XLOOKUP($B4,TC_Fechas,TC_Venta_Rango,"",-1)="","",_xlfn.XLOOKUP($B4,TC_Fechas,TC_Venta_Rango,"",-1)),""))) | O4: =IF(OR($C4="",$N4=""),"",ROUND($J4*$N4,2)+ROUND($K4*$N4,2)) | P4: =IF($G4="","",IFERROR(INDEX(Catalogo_Tasas,MATCH($G4,Catalogo_Codigos,0)),"")) | Q4: =IF($G4="","",IFERROR(INDEX(Catalogo_Umbrales,MATCH($G4,Catalogo_Codigos,0)),"")) | R4: =IF(OR($C4="",$P4="",$O4=""),"",IF($F4<>"FACTURA","NO",IF(AND($P4>0,$O4>$Q4),"SI","NO"))) | S4: =IF($R4="SI",ROUND($O4*$P4,2),IF($C4="","",0)) | T4: 721.44 | U4: =IF($C4="","",IF($R4<>"SI","",IF($T4="","SIN DATO",IF(ABS($T4-$S4)<=0.5,"OK","REVISAR")))) | W4: =IF(OR($C4="",$N4=""),"",IF($F4="RHE",ROUND($L4-$V4,2),ROUND($L4-($S4/$N4),2))) | AA4: PENDIENTE | AB4: ADMINISTRATIVO
A5: 2 | B5: 46254 | C5: FL09-00136064 | D5: 20419195317 | E5: INKA TERRA PERU S.A.C. (INKATERRA MACHU PICCHU PUEBLO HOTEL) | F5: FACTURA | G5: N/A | H5: =IF($G5="","",IFERROR(INDEX(Catalogo_Etiquetas,MATCH($G5,Catalogo_Codigos,0)),"CODIGO NO VALIDO")) | I5: USD | J5: 806.96 | K5: 0 | L5: =IF($C5="","",$J5+$K5) | M5: 639 | N5: =IF($C5="","",IF($I5="PEN",1,IFERROR(IF(_xlfn.XLOOKUP($B5,TC_Fechas,TC_Venta_Rango,"",-1)="","",_xlfn.XLOOKUP($B5,TC_Fechas,TC_Venta_Rango,"",-1)),""))) | O5: =IF(OR($C5="",$N5=""),"",ROUND($J5*$N5,2)+ROUND($K5*$N5,2)) | P5: =IF($G5="","",IFERROR(INDEX(Catalogo_Tasas,MATCH($G5,Catalogo_Codigos,0)),"")) | Q5: =IF($G5="","",IFERROR(INDEX(Catalogo_Umbrales,MATCH($G5,Catalogo_Codigos,0)),"")) | R5: =IF(OR($C5="",$P5="",$O5=""),"",IF($F5<>"FACTURA","NO",IF(AND($P5>0,$O5>$Q5),"SI","NO"))) | S5: =IF($R5="SI",ROUND($O5*$P5,2),IF($C5="","",0)) | U5: =IF($C5="","",IF($R5<>"SI","",IF($T5="","SIN DATO",IF(ABS($T5-$S5)<=0.5,"OK","REVISAR")))) | W5: =IF(OR($C5="",$N5=""),"",IF($F5="RHE",ROUND($L5-$V5,2),ROUND($L5-($S5/$N5),2))) | AA5: PENDIENTE | AB5: PROVEEDOR
A6: 3 | B6: 46254 | C6: F078-00006851 | D6: 20510931514 | E6: PERUVIAN TOURS AGENCY S.A.C. (ARANWA - HOTEL COLCA) | F6: FACTURA | G6: N/A | H6: =IF($G6="","",IFERROR(INDEX(Catalogo_Etiquetas,MATCH($G6,Catalogo_Codigos,0)),"CODIGO NO VALIDO")) | I6: USD | J6: 936 | K6: 0 | L6: =IF($C6="","",$J6+$K6) | M6: 639 | N6: =IF($C6="","",IF($I6="PEN",1,IFERROR(IF(_xlfn.XLOOKUP($B6,TC_Fechas,TC_Venta_Rango,"",-1)="","",_xlfn.XLOOKUP($B6,TC_Fechas,TC_Venta_Rango,"",-1)),""))) | O6: =IF(OR($C6="",$N6=""),"",ROUND($J6*$N6,2)+ROUND($K6*$N6,2)) | P6: =IF($G6="","",IFERROR(INDEX(Catalogo_Tasas,MATCH($G6,Catalogo_Codigos,0)),"")) | Q6: =IF($G6="","",IFERROR(INDEX(Catalogo_Umbrales,MATCH($G6,Catalogo_Codigos,0)),"")) | R6: =IF(OR($C6="",$P6="",$O6=""),"",IF($F6<>"FACTURA","NO",IF(AND($P6>0,$O6>$Q6),"SI","NO"))) | S6: =IF($R6="SI",ROUND($O6*$P6,2),IF($C6="","",0)) | U6: =IF($C6="","",IF($R6<>"SI","",IF($T6="","SIN DATO",IF(ABS($T6-$S6)<=0.5,"OK","REVISAR")))) | W6: =IF(OR($C6="",$N6=""),"",IF($F6="RHE",ROUND($L6-$V6,2),ROUND($L6-($S6/$N6),2))) | AA6: PENDIENTE | AB6: PROVEEDOR
A7: 4 | B7: 46254 | C7: F007-00024508 | D7: 20536047906 | E7: HOTELERIA PERUANA S.A.C. (TIERRA VIVA HOTELS) | F7: FACTURA | G7: N/A | H7: =IF($G7="","",IFERROR(INDEX(Catalogo_Etiquetas,MATCH($G7,Catalogo_Codigos,0)),"CODIGO NO VALIDO")) | I7: USD | J7: 68 | K7: 0 | L7: =IF($C7="","",$J7+$K7) | M7: 639 | N7: =IF($C7="","",IF($I7="PEN",1,IFERROR(IF(_xlfn.XLOOKUP($B7,TC_Fechas,TC_Venta_Rango,"",-1)="","",_xlfn.XLOOKUP($B7,TC_Fechas,TC_Venta_Rango,"",-1)),""))) | O7: =IF(OR($C7="",$N7=""),"",ROUND($J7*$N7,2)+ROUND($K7*$N7,2)) | P7: =IF($G7="","",IFERROR(INDEX(Catalogo_Tasas,MATCH($G7,Catalogo_Codigos,0)),"")) | Q7: =IF($G7="","",IFERROR(INDEX(Catalogo_Umbrales,MATCH($G7,Catalogo_Codigos,0)),"")) | R7: =IF(OR($C7="",$P7="",$O7=""),"",IF($F7<>"FACTURA","NO",IF(AND($P7>0,$O7>$Q7),"SI","NO"))) | S7: =IF($R7="SI",ROUND($O7*$P7,2),IF($C7="","",0)) | U7: =IF($C7="","",IF($R7<>"SI","",IF($T7="","SIN DATO",IF(ABS($T7-$S7)<=0.5,"OK","REVISAR")))) | W7: =IF(OR($C7="",$N7=""),"",IF($F7="RHE",ROUND($L7-$V7,2),ROUND($L7-($S7/$N7),2))) | AA7: PENDIENTE | AB7: PROVEEDOR
A8: 5 | B8: 46254 | C8: F008-00035739 | D8: 20536047906 | E8: HOTELERIA PERUANA S.A.C. (TIERRA VIVA HOTELS) | F8: FACTURA | G8: N/A | H8: =IF($G8="","",IFERROR(INDEX(Catalogo_Etiquetas,MATCH($G8,Catalogo_Codigos,0)),"CODIGO NO VALIDO")) | I8: USD | J8: 152 | K8: 0 | L8: =IF($C8="","",$J8+$K8) | M8: 639 | N8: =IF($C8="","",IF($I8="PEN",1,IFERROR(IF(_xlfn.XLOOKUP($B8,TC_Fechas,TC_Venta_Rango,"",-1)="","",_xlfn.XLOOKUP($B8,TC_Fechas,TC_Venta_Rango,"",-1)),""))) | O8: =IF(OR($C8="",$N8=""),"",ROUND($J8*$N8,2)+ROUND($K8*$N8,2)) | P8: =IF($G8="","",IFERROR(INDEX(Catalogo_Tasas,MATCH($G8,Catalogo_Codigos,0)),"")) | Q8: =IF($G8="","",IFERROR(INDEX(Catalogo_Umbrales,MATCH($G8,Catalogo_Codigos,0)),"")) | R8: =IF(OR($C8="",$P8="",$O8=""),"",IF($F8<>"FACTURA","NO",IF(AND($P8>0,$O8>$Q8),"SI","NO"))) | S8: =IF($R8="SI",ROUND($O8*$P8,2),IF($C8="","",0)) | U8: =IF($C8="","",IF($R8<>"SI","",IF($T8="","SIN DATO",IF(ABS($T8-$S8)<=0.5,"OK","REVISAR")))) | W8: =IF(OR($C8="",$N8=""),"",IF($F8="RHE",ROUND($L8-$V8,2),ROUND($L8-($S8/$N8),2))) | AA8: PENDIENTE | AB8: PROVEEDOR
A9: 6 | B9: 46254 | C9: F003-00017125 | D9: 20563817675 | E9: CCM HOTEL GROUP S.A.C. (CASA REPUBLICA BARRANCO) | F9: FACTURA | G9: N/A | H9: =IF($G9="","",IFERROR(INDEX(Catalogo_Etiquetas,MATCH($G9,Catalogo_Codigos,0)),"CODIGO NO VALIDO")) | I9: USD | J9: 196.27 | K9: 18.73 | L9: =IF($C9="","",$J9+$K9) | M9: 639 | N9: =IF($C9="","",IF($I9="PEN",1,IFERROR(IF(_xlfn.XLOOKUP($B9,TC_Fechas,TC_Venta_Rango,"",-1)="","",_xlfn.XLOOKUP($B9,TC_Fechas,TC_Venta_Rango,"",-1)),""))) | O9: =IF(OR($C9="",$N9=""),"",ROUND($J9*$N9,2)+ROUND($K9*$N9,2)) | P9: =IF($G9="","",IFERROR(INDEX(Catalogo_Tasas,MATCH($G9,Catalogo_Codigos,0)),"")) | Q9: =IF($G9="","",IFERROR(INDEX(Catalogo_Umbrales,MATCH($G9,Catalogo_Codigos,0)),"")) | R9: =IF(OR($C9="",$P9="",$O9=""),"",IF($F9<>"FACTURA","NO",IF(AND($P9>0,$O9>$Q9),"SI","NO"))) | S9: =IF($R9="SI",ROUND($O9*$P9,2),IF($C9="","",0)) | U9: =IF($C9="","",IF($R9<>"SI","",IF($T9="","SIN DATO",IF(ABS($T9-$S9)<=0.5,"OK","REVISAR")))) | W9: =IF(OR($C9="",$N9=""),"",IF($F9="RHE",ROUND($L9-$V9,2),ROUND($L9-($S9/$N9),2))) | AA9: PENDIENTE | AB9: PROVEEDOR
A10: 7 | B10: 46254 | C10: F003-00017127 | D10: 20563817675 | E10: CCM HOTEL GROUP S.A.C. (CASA REPUBLICA BARRANCO) | F10: FACTURA | G10: N/A | H10: =IF($G10="","",IFERROR(INDEX(Catalogo_Etiquetas,MATCH($G10,Catalogo_Codigos,0)),"CODIGO NO VALIDO")) | I10: USD | J10: 230 | K10: 0 | L10: =IF($C10="","",$J10+$K10) | M10: 639 | N10: =IF($C10="","",IF($I10="PEN",1,IFERROR(IF(_xlfn.XLOOKUP($B10,TC_Fechas,TC_Venta_Rango,"",-1)="","",_xlfn.XLOOKUP($B10,TC_Fechas,TC_Venta_Rango,"",-1)),""))) | O10: =IF(OR($C10="",$N10=""),"",ROUND($J10*$N10,2)+ROUND($K10*$N10,2)) | P10: =IF($G10="","",IFERROR(INDEX(Catalogo_Tasas,MATCH($G10,Catalogo_Codigos,0)),"")) | Q10: =IF($G10="","",IFERROR(INDEX(Catalogo_Umbrales,MATCH($G10,Catalogo_Codigos,0)),"")) | R10: =IF(OR($C10="",$P10="",$O10=""),"",IF($F10<>"FACTURA","NO",IF(AND($P10>0,$O10>$Q10),"SI","NO"))) | S10: =IF($R10="SI",ROUND($O10*$P10,2),IF($C10="","",0)) | U10: =IF($C10="","",IF($R10<>"SI","",IF($T10="","SIN DATO",IF(ABS($T10-$S10)<=0.5,"OK","REVISAR")))) | W10: =IF(OR($C10="",$N10=""),"",IF($F10="RHE",ROUND($L10-$V10,2),ROUND($L10-($S10/$N10),2))) | AA10: PENDIENTE | AB10: PROVEEDOR
A11: 8 | B11: 46254 | C11: FNC3-00001843 | D11: 20563817675 | E11: CCM HOTEL GROUP S.A.C. (CASA REPUBLICA BARRANCO) | F11: NOTA DE CREDITO | G11: N/A | H11: =IF($G11="","",IFERROR(INDEX(Catalogo_Etiquetas,MATCH($G11,Catalogo_Codigos,0)),"CODIGO NO VALIDO")) | I11: USD | J11: -209.96 | K11: -20.04 | L11: =IF($C11="","",$J11+$K11) | M11: 639 | N11: =IF($C11="","",IF($I11="PEN",1,IFERROR(IF(_xlfn.XLOOKUP($B11,TC_Fechas,TC_Venta_Rango,"",-1)="","",_xlfn.XLOOKUP($B11,TC_Fechas,TC_Venta_Rango,"",-1)),""))) | O11: =IF(OR($C11="",$N11=""),"",ROUND($J11*$N11,2)+ROUND($K11*$N11,2)) | P11: =IF($G11="","",IFERROR(INDEX(Catalogo_Tasas,MATCH($G11,Catalogo_Codigos,0)),"")) | Q11: =IF($G11="","",IFERROR(INDEX(Catalogo_Umbrales,MATCH($G11,Catalogo_Codigos,0)),"")) | R11: =IF(OR($C11="",$P11="",$O11=""),"",IF($F11<>"FACTURA","NO",IF(AND($P11>0,$O11>$Q11),"SI","NO"))) | S11: =IF($R11="SI",ROUND($O11*$P11,2),IF($C11="","",0)) | U11: =IF($C11="","",IF($R11<>"SI","",IF($T11="","SIN DATO",IF(ABS($T11-$S11)<=0.5,"OK","REVISAR")))) | W11: =IF(OR($C11="",$N11=""),"",IF($F11="RHE",ROUND($L11-$V11,2),ROUND($L11-($S11/$N11),2))) | AA11: PENDIENTE | AB11: PROVEEDOR
A12: 9 | B12: 46254 | C12: E001-7201 | D12: 20225253529 | E12: ARCOBALENO SOCIEDAD COMERCIAL DE RESPONSABILIDAD LIMITADA | F12: FACTURA | G12: 037 | H12: =IF($G12="","",IFERROR(INDEX(Catalogo_Etiquetas,MATCH($G12,Catalogo_Codigos,0)),"CODIGO NO VALIDO")) | I12: USD | J12: 186.03 | K12: 33.49 | L12: =IF($C12="","",$J12+$K12) | M12: 639 | N12: =IF($C12="","",IF($I12="PEN",1,IFERROR(IF(_xlfn.XLOOKUP($B12,TC_Fechas,TC_Venta_Rango,"",-1)="","",_xlfn.XLOOKUP($B12,TC_Fechas,TC_Venta_Rango,"",-1)),""))) | O12: =IF(OR($C12="",$N12=""),"",ROUND($J12*$N12,2)+ROUND($K12*$N12,2)) | P12: =IF($G12="","",IFERROR(INDEX(Catalogo_Tasas,MATCH($G12,Catalogo_Codigos,0)),"")) | Q12: =IF($G12="","",IFERROR(INDEX(Catalogo_Umbrales,MATCH($G12,Catalogo_Codigos,0)),"")) | R12: =IF(OR($C12="",$P12="",$O12=""),"",IF($F12<>"FACTURA","NO",IF(AND($P12>0,$O12>$Q12),"SI","NO"))) | S12: =IF($R12="SI",ROUND($O12*$P12,2),IF($C12="","",0)) | T12: 89 | U12: =IF($C12="","",IF($R12<>"SI","",IF($T12="","SIN DATO",IF(ABS($T12-$S12)<=0.5,"OK","REVISAR")))) | W12: =IF(OR($C12="",$N12=""),"",IF($F12="RHE",ROUND($L12-$V12,2),ROUND($L12-($S12/$N12),2))) | AA12: PENDIENTE | AB12: PROVEEDOR
A13: 10 | B13: =DATE(2026,8,11) | C13: F001-0003289 | D13: 20510815522 | E13: AERODIANA | F13: NOTA DE CREDITO | G13: N/A | H13: =IF($G13="","",IFERROR(INDEX(Catalogo_Etiquetas,MATCH($G13,Catalogo_Codigos,0)),"CODIGO NO VALIDO")) | I13: USD | J13: -498.31 | K13: -89.69 | L13: =IF($C13="","",$J13+$K13) | M13: 639 | N13: =IF($C13="","",IF($I13="PEN",1,IFERROR(IF(_xlfn.XLOOKUP($B13,TC_Fechas,TC_Venta_Rango,"",-1)="","",_xlfn.XLOOKUP($B13,TC_Fechas,TC_Venta_Rango,"",-1)),""))) | O13: =IF(OR($C13="",$N13=""),"",ROUND($J13*$N13,2)+ROUND($K13*$N13,2)) | P13: =IF($G13="","",IFERROR(INDEX(Catalogo_Tasas,MATCH($G13,Catalogo_Codigos,0)),"")) | Q13: =IF($G13="","",IFERROR(INDEX(Catalogo_Umbrales,MATCH($G13,Catalogo_Codigos,0)),"")) | R13: =IF(OR($C13="",$P13="",$O13=""),"",IF($F13<>"FACTURA","NO",IF(AND($P13>0,$O13>$Q13),"SI","NO"))) | S13: =IF($R13="SI",ROUND($O13*$P13,2),IF($C13="","",0)) | U13: =IF($C13="","",IF($R13<>"SI","",IF($T13="","SIN DATO",IF(ABS($T13-$S13)<=0.5,"OK","REVISAR")))) | W13: =IF(OR($C13="",$N13=""),"",IF($F13="RHE",ROUND($L13-$V13,2),ROUND($L13-($S13/$N13),2))) | AB13: PROVEEDOR
A14: 11 | B14: =DATE(2026,8,6) | C14: F001-038853 | D14: 20358806237 | E14: AMERICANA DE TURISMO E.I.R.L. | F14: FACTURA | G14: N/A | H14: =IF($G14="","",IFERROR(INDEX(Catalogo_Etiquetas,MATCH($G14,Catalogo_Codigos,0)),"CODIGO NO VALIDO")) | I14: USD | J14: 61.02 | K14: 10.98 | L14: =IF($C14="","",$J14+$K14) | M14: 639 | N14: =IF($C14="","",IF($I14="PEN",1,IFERROR(IF(_xlfn.XLOOKUP($B14,TC_Fechas,TC_Venta_Rango,"",-1)="","",_xlfn.XLOOKUP($B14,TC_Fechas,TC_Venta_Rango,"",-1)),""))) | O14: =IF(OR($C14="",$N14=""),"",ROUND($J14*$N14,2)+ROUND($K14*$N14,2)) | P14: =IF($G14="","",IFERROR(INDEX(Catalogo_Tasas,MATCH($G14,Catalogo_Codigos,0)),"")) | Q14: =IF($G14="","",IFERROR(INDEX(Catalogo_Umbrales,MATCH($G14,Catalogo_Codigos,0)),"")) | R14: =IF(OR($C14="",$P14="",$O14=""),"",IF($F14<>"FACTURA","NO",IF(AND($P14>0,$O14>$Q14),"SI","NO"))) | S14: =IF($R14="SI",ROUND($O14*$P14,2),IF($C14="","",0)) | U14: =IF($C14="","",IF($R14<>"SI","",IF($T14="","SIN DATO",IF(ABS($T14-$S14)<=0.5,"OK","REVISAR")))) | W14: =IF(OR($C14="",$N14=""),"",IF($F14="RHE",ROUND($L14-$V14,2),ROUND($L14-($S14/$N14),2))) | AB14: PROVEEDOR
A15: 12 | B15: =DATE(2026,8,10) | C15: E001- 173 | D15: 10408744151 | E15: BEOUTIS BAZAN URSULA CATHERINE | F15: RHE | G15: N/A | H15: =IF($G15="","",IFERROR(INDEX(Catalogo_Etiquetas,MATCH($G15,Catalogo_Codigos,0)),"CODIGO NO VALIDO")) | I15: PEN | J15: 1025 | K15: 0 | L15: =IF($C15="","",$J15+$K15) | M15: 632 | N15: =IF($C15="","",IF($I15="PEN",1,IFERROR(IF(_xlfn.XLOOKUP($B15,TC_Fechas,TC_Venta_Rango,"",-1)="","",_xlfn.XLOOKUP($B15,TC_Fechas,TC_Venta_Rango,"",-1)),""))) | O15: =IF(OR($C15="",$N15=""),"",ROUND($J15*$N15,2)+ROUND($K15*$N15,2)) | P15: =IF($G15="","",IFERROR(INDEX(Catalogo_Tasas,MATCH($G15,Catalogo_Codigos,0)),"")) | Q15: =IF($G15="","",IFERROR(INDEX(Catalogo_Umbrales,MATCH($G15,Catalogo_Codigos,0)),"")) | R15: =IF(OR($C15="",$P15="",$O15=""),"",IF($F15<>"FACTURA","NO",IF(AND($P15>0,$O15>$Q15),"SI","NO"))) | S15: =IF($R15="SI",ROUND($O15*$P15,2),IF($C15="","",0)) | U15: =IF($C15="","",IF($R15<>"SI","",IF($T15="","SIN DATO",IF(ABS($T15-$S15)<=0.5,"OK","REVISAR")))) | W15: =IF(OR($C15="",$N15=""),"",IF($F15="RHE",ROUND($L15-$V15,2),ROUND($L15-($S15/$N15),2))) | AB15: ADMINISTRATIVO
A16: 13 | B16: =DATE(2026,8,14) | C16: E001-129 | D16: 10239541181 | E16: CALLAÃ‘AUPA DE HENDRICKSON FLORA | F16: RHE | G16: N/A | H16: =IF($G16="","",IFERROR(INDEX(Catalogo_Etiquetas,MATCH($G16,Catalogo_Codigos,0)),"CODIGO NO VALIDO")) | I16: USD | J16: 65 | K16: 0 | L16: =IF($C16="","",$J16+$K16) | M16: 632 | N16: =IF($C16="","",IF($I16="PEN",1,IFERROR(IF(_xlfn.XLOOKUP($B16,TC_Fechas,TC_Venta_Rango,"",-1)="","",_xlfn.XLOOKUP($B16,TC_Fechas,TC_Venta_Rango,"",-1)),""))) | O16: =IF(OR($C16="",$N16=""),"",ROUND($J16*$N16,2)+ROUND($K16*$N16,2)) | P16: =IF($G16="","",IFERROR(INDEX(Catalogo_Tasas,MATCH($G16,Catalogo_Codigos,0)),"")) | Q16: =IF($G16="","",IFERROR(INDEX(Catalogo_Umbrales,MATCH($G16,Catalogo_Codigos,0)),"")) | R16: =IF(OR($C16="",$P16="",$O16=""),"",IF($F16<>"FACTURA","NO",IF(AND($P16>0,$O16>$Q16),"SI","NO"))) | S16: =IF($R16="SI",ROUND($O16*$P16,2),IF($C16="","",0)) | U16: =IF($C16="","",IF($R16<>"SI","",IF($T16="","SIN DATO",IF(ABS($T16-$S16)<=0.5,"OK","REVISAR")))) | V16: 7.8 | W16: =IF(OR($C16="",$N16=""),"",IF($F16="RHE",ROUND($L16-$V16,2),ROUND($L16-($S16/$N16),2))) | AB16: PROVEEDOR
A17: 14 | B17: =DATE(2026,8,12) | C17: FA02-00001849 | D17: 20527992525 | E17: CUSCO RESTAURANTS S.A.C. | F17: FACTURA | G17: N/A | H17: =IF($G17="","",IFERROR(INDEX(Catalogo_Etiquetas,MATCH($G17,Catalogo_Codigos,0)),"CODIGO NO VALIDO")) | I17: USD | J17: 54.69 | K17: 9.84 | L17: =IF($C17="","",$J17+$K17) | M17: 639 | N17: =IF($C17="","",IF($I17="PEN",1,IFERROR(IF(_xlfn.XLOOKUP($B17,TC_Fechas,TC_Venta_Rango,"",-1)="","",_xlfn.XLOOKUP($B17,TC_Fechas,TC_Venta_Rango,"",-1)),""))) | O17: =IF(OR($C17="",$N17=""),"",ROUND($J17*$N17,2)+ROUND($K17*$N17,2)) | P17: =IF($G17="","",IFERROR(INDEX(Catalogo_Tasas,MATCH($G17,Catalogo_Codigos,0)),"")) | Q17: =IF($G17="","",IFERROR(INDEX(Catalogo_Umbrales,MATCH($G17,Catalogo_Codigos,0)),"")) | R17: =IF(OR($C17="",$P17="",$O17=""),"",IF($F17<>"FACTURA","NO",IF(AND($P17>0,$O17>$Q17),"SI","NO"))) | S17: =IF($R17="SI",ROUND($O17*$P17,2),IF($C17="","",0)) | U17: =IF($C17="","",IF($R17<>"SI","",IF($T17="","SIN DATO",IF(ABS($T17-$S17)<=0.5,"OK","REVISAR")))) | W17: =IF(OR($C17="",$N17=""),"",IF($F17="RHE",ROUND($L17-$V17,2),ROUND($L17-($S17/$N17),2))) | AB17: PROVEEDOR
A18: 15 | B18: =DATE(2026,8,6) | C18: F005-018812 | D18: 20252796623 | E18: GRESCO S.A.C. | F18: FACTURA | G18: N/A | H18: =IF($G18="","",IFERROR(INDEX(Catalogo_Etiquetas,MATCH($G18,Catalogo_Codigos,0)),"CODIGO NO VALIDO")) | I18: PEN | J18: 158.73 | K18: 28.57 | L18: =IF($C18="","",$J18+$K18) | M18: 639 | N18: =IF($C18="","",IF($I18="PEN",1,IFERROR(IF(_xlfn.XLOOKUP($B18,TC_Fechas,TC_Venta_Rango,"",-1)="","",_xlfn.XLOOKUP($B18,TC_Fechas,TC_Venta_Rango,"",-1)),""))) | O18: =IF(OR($C18="",$N18=""),"",ROUND($J18*$N18,2)+ROUND($K18*$N18,2)) | P18: =IF($G18="","",IFERROR(INDEX(Catalogo_Tasas,MATCH($G18,Catalogo_Codigos,0)),"")) | Q18: =IF($G18="","",IFERROR(INDEX(Catalogo_Umbrales,MATCH($G18,Catalogo_Codigos,0)),"")) | R18: =IF(OR($C18="",$P18="",$O18=""),"",IF($F18<>"FACTURA","NO",IF(AND($P18>0,$O18>$Q18),"SI","NO"))) | S18: =IF($R18="SI",ROUND($O18*$P18,2),IF($C18="","",0)) | U18: =IF($C18="","",IF($R18<>"SI","",IF($T18="","SIN DATO",IF(ABS($T18-$S18)<=0.5,"OK","REVISAR")))) | W18: =IF(OR($C18="",$N18=""),"",IF($F18="RHE",ROUND($L18-$V18,2),ROUND($L18-($S18/$N18),2))) | AB18: PROVEEDOR
A19: 16 | B19: =DATE(2026,8,4) | C19: E001- 558 | D19: 10239898993 | E19: HANCO ASTETE ANDY | F19: RHE | G19: N/A | H19: =IF($G19="","",IFERROR(INDEX(Catalogo_Etiquetas,MATCH($G19,Catalogo_Codigos,0)),"CODIGO NO VALIDO")) | I19: USD | J19: 75 | K19: 0 | L19: =IF($C19="","",$J19+$K19) | M19: 632 | N19: =IF($C19="","",IF($I19="PEN",1,IFERROR(IF(_xlfn.XLOOKUP($B19,TC_Fechas,TC_Venta_Rango,"",-1)="","",_xlfn.XLOOKUP($B19,TC_Fechas,TC_Venta_Rango,"",-1)),""))) | O19: =IF(OR($C19="",$N19=""),"",ROUND($J19*$N19,2)+ROUND($K19*$N19,2)) | P19: =IF($G19="","",IFERROR(INDEX(Catalogo_Tasas,MATCH($G19,Catalogo_Codigos,0)),"")) | Q19: =IF($G19="","",IFERROR(INDEX(Catalogo_Umbrales,MATCH($G19,Catalogo_Codigos,0)),"")) | R19: =IF(OR($C19="",$P19="",$O19=""),"",IF($F19<>"FACTURA","NO",IF(AND($P19>0,$O19>$Q19),"SI","NO"))) | S19: =IF($R19="SI",ROUND($O19*$P19,2),IF($C19="","",0)) | U19: =IF($C19="","",IF($R19<>"SI","",IF($T19="","SIN DATO",IF(ABS($T19-$S19)<=0.5,"OK","REVISAR")))) | W19: =IF(OR($C19="",$N19=""),"",IF($F19="RHE",ROUND($L19-$V19,2),ROUND($L19-($S19/$N19),2))) | AB19: PROVEEDOR
A20: 17 | B20: =DATE(2026,8,14) | C20: F006-00003152 | D20: 20610235736 | E20: HOTELES LA HACIENDA S.A.C. | F20: FACTURA | G20: N/A | H20: =IF($G20="","",IFERROR(INDEX(Catalogo_Etiquetas,MATCH($G20,Catalogo_Codigos,0)),"CODIGO NO VALIDO")) | I20: USD | J20: 460.18 | K20: 0 | L20: =IF($C20="","",$J20+$K20) | M20: 639 | N20: =IF($C20="","",IF($I20="PEN",1,IFERROR(IF(_xlfn.XLOOKUP($B20,TC_Fechas,TC_Venta_Rango,"",-1)="","",_xlfn.XLOOKUP($B20,TC_Fechas,TC_Venta_Rango,"",-1)),""))) | O20: =IF(OR($C20="",$N20=""),"",ROUND($J20*$N20,2)+ROUND($K20*$N20,2)) | P20: =IF($G20="","",IFERROR(INDEX(Catalogo_Tasas,MATCH($G20,Catalogo_Codigos,0)),"")) | Q20: =IF($G20="","",IFERROR(INDEX(Catalogo_Umbrales,MATCH($G20,Catalogo_Codigos,0)),"")) | R20: =IF(OR($C20="",$P20="",$O20=""),"",IF($F20<>"FACTURA","NO",IF(AND($P20>0,$O20>$Q20),"SI","NO"))) | S20: =IF($R20="SI",ROUND($O20*$P20,2),IF($C20="","",0)) | U20: =IF($C20="","",IF($R20<>"SI","",IF($T20="","SIN DATO",IF(ABS($T20-$S20)<=0.5,"OK","REVISAR")))) | W20: =IF(OR($C20="",$N20=""),"",IF($F20="RHE",ROUND($L20-$V20,2),ROUND($L20-($S20/$N20),2))) | AB20: PROVEEDOR
A21: 18 | B21: =DATE(2026,8,4) | C21: E001-1678 | D21: 20602511007 | E21: INVERSIONES FENIX TOURS E.I.R.L. | F21: FACTURA | G21: 026 | H21: =IF($G21="","",IFERROR(INDEX(Catalogo_Etiquetas,MATCH($G21,Catalogo_Codigos,0)),"CODIGO NO VALIDO")) | I21: USD | J21: 282.2 | K21: 50.8 | L21: =IF($C21="","",$J21+$K21) | M21: 631 | N21: =IF($C21="","",IF($I21="PEN",1,IFERROR(IF(_xlfn.XLOOKUP($B21,TC_Fechas,TC_Venta_Rango,"",-1)="","",_xlfn.XLOOKUP($B21,TC_Fechas,TC_Venta_Rango,"",-1)),""))) | O21: =IF(OR($C21="",$N21=""),"",ROUND($J21*$N21,2)+ROUND($K21*$N21,2)) | P21: =IF($G21="","",IFERROR(INDEX(Catalogo_Tasas,MATCH($G21,Catalogo_Codigos,0)),"")) | Q21: =IF($G21="","",IFERROR(INDEX(Catalogo_Umbrales,MATCH($G21,Catalogo_Codigos,0)),"")) | R21: =IF(OR($C21="",$P21="",$O21=""),"",IF($F21<>"FACTURA","NO",IF(AND($P21>0,$O21>$Q21),"SI","NO"))) | S21: =IF($R21="SI",ROUND($O21*$P21,2),IF($C21="","",0)) | T21: 113 | U21: =IF($C21="","",IF($R21<>"SI","",IF($T21="","SIN DATO",IF(ABS($T21-$S21)<=0.5,"OK","REVISAR")))) | W21: =IF(OR($C21="",$N21=""),"",IF($F21="RHE",ROUND($L21-$V21,2),ROUND($L21-($S21/$N21),2))) | AB21: PROVEEDOR
A22: 19 | B22: =DATE(2026,8,14) | C22: E001-2661 | D22: 20602860958 | E22: J & R TURISMO E.I.R.L. | F22: FACTURA | G22: 026 | H22: =IF($G22="","",IFERROR(INDEX(Catalogo_Etiquetas,MATCH($G22,Catalogo_Codigos,0)),"CODIGO NO VALIDO")) | I22: USD | J22: 660 | K22: 118.8 | L22: =IF($C22="","",$J22+$K22) | M22: 631 | N22: =IF($C22="","",IF($I22="PEN",1,IFERROR(IF(_xlfn.XLOOKUP($B22,TC_Fechas,TC_Venta_Rango,"",-1)="","",_xlfn.XLOOKUP($B22,TC_Fechas,TC_Venta_Rango,"",-1)),""))) | O22: =IF(OR($C22="",$N22=""),"",ROUND($J22*$N22,2)+ROUND($K22*$N22,2)) | P22: =IF($G22="","",IFERROR(INDEX(Catalogo_Tasas,MATCH($G22,Catalogo_Codigos,0)),"")) | Q22: =IF($G22="","",IFERROR(INDEX(Catalogo_Umbrales,MATCH($G22,Catalogo_Codigos,0)),"")) | R22: =IF(OR($C22="",$P22="",$O22=""),"",IF($F22<>"FACTURA","NO",IF(AND($P22>0,$O22>$Q22),"SI","NO"))) | S22: =IF($R22="SI",ROUND($O22*$P22,2),IF($C22="","",0)) | T22: 262.53 | U22: =IF($C22="","",IF($R22<>"SI","",IF($T22="","SIN DATO",IF(ABS($T22-$S22)<=0.5,"OK","REVISAR")))) | W22: =IF(OR($C22="",$N22=""),"",IF($F22="RHE",ROUND($L22-$V22,2),ROUND($L22-($S22/$N22),2))) | AB22: PROVEEDOR
A23: 20 | B23: =DATE(2026,8,13) | C23: E001-9 | D23: 10726172591 | E23: LUCERO KARLA MADGE BOCANEGRA | F23: RHE | G23: N/A | H23: =IF($G23="","",IFERROR(INDEX(Catalogo_Etiquetas,MATCH($G23,Catalogo_Codigos,0)),"CODIGO NO VALIDO")) | I23: PEN | J23: 1100 | K23: 0 | L23: =IF($C23="","",$J23+$K23) | M23: 632 | N23: =IF($C23="","",IF($I23="PEN",1,IFERROR(IF(_xlfn.XLOOKUP($B23,TC_Fechas,TC_Venta_Rango,"",-1)="","",_xlfn.XLOOKUP($B23,TC_Fechas,TC_Venta_Rango,"",-1)),""))) | O23: =IF(OR($C23="",$N23=""),"",ROUND($J23*$N23,2)+ROUND($K23*$N23,2)) | P23: =IF($G23="","",IFERROR(INDEX(Catalogo_Tasas,MATCH($G23,Catalogo_Codigos,0)),"")) | Q23: =IF($G23="","",IFERROR(INDEX(Catalogo_Umbrales,MATCH($G23,Catalogo_Codigos,0)),"")) | R23: =IF(OR($C23="",$P23="",$O23=""),"",IF($F23<>"FACTURA","NO",IF(AND($P23>0,$O23>$Q23),"SI","NO"))) | S23: =IF($R23="SI",ROUND($O23*$P23,2),IF($C23="","",0)) | U23: =IF($C23="","",IF($R23<>"SI","",IF($T23="","SIN DATO",IF(ABS($T23-$S23)<=0.5,"OK","REVISAR")))) | W23: =IF(OR($C23="",$N23=""),"",IF($F23="RHE",ROUND($L23-$V23,2),ROUND($L23-($S23/$N23),2))) | AB23: ADMINISTRATIVO
A24: 21 | B24: =DATE(2026,8,14) | C24: E001- 32 | D24: 10490200784 | E24: NIKOLSKAIA VALENTINA | F24: RHE | G24: N/A | H24: =IF($G24="","",IFERROR(INDEX(Catalogo_Etiquetas,MATCH($G24,Catalogo_Codigos,0)),"CODIGO NO VALIDO")) | I24: USD | J24: 700 | K24: 0 | L24: =IF($C24="","",$J24+$K24) | M24: 632 | N24: =IF($C24="","",IF($I24="PEN",1,IFERROR(IF(_xlfn.XLOOKUP($B24,TC_Fechas,TC_Venta_Rango,"",-1)="","",_xlfn.XLOOKUP($B24,TC_Fechas,TC_Venta_Rango,"",-1)),""))) | O24: =IF(OR($C24="",$N24=""),"",ROUND($J24*$N24,2)+ROUND($K24*$N24,2)) | P24: =IF($G24="","",IFERROR(INDEX(Catalogo_Tasas,MATCH($G24,Catalogo_Codigos,0)),"")) | Q24: =IF($G24="","",IFERROR(INDEX(Catalogo_Umbrales,MATCH($G24,Catalogo_Codigos,0)),"")) | R24: =IF(OR($C24="",$P24="",$O24=""),"",IF($F24<>"FACTURA","NO",IF(AND($P24>0,$O24>$Q24),"SI","NO"))) | S24: =IF($R24="SI",ROUND($O24*$P24,2),IF($C24="","",0)) | U24: =IF($C24="","",IF($R24<>"SI","",IF($T24="","SIN DATO",IF(ABS($T24-$S24)<=0.5,"OK","REVISAR")))) | W24: =IF(OR($C24="",$N24=""),"",IF($F24="RHE",ROUND($L24-$V24,2),ROUND($L24-($S24/$N24),2))) | AB24: PROVEEDOR
A25: 22 | B25: =DATE(2026,8,12) | C25: F001-00000737 | D25: 20603386214 | E25: PERUVIAN CULTURE TRAVEL AGENCIA DE VIAJES Y TURISMO S.R.L. | F25: FACTURA | G25: N/A | H25: =IF($G25="","",IFERROR(INDEX(Catalogo_Etiquetas,MATCH($G25,Catalogo_Codigos,0)),"CODIGO NO VALIDO")) | I25: USD | J25: 61.02 | K25: 10.98 | L25: =IF($C25="","",$J25+$K25) | M25: 639 | N25: =IF($C25="","",IF($I25="PEN",1,IFERROR(IF(_xlfn.XLOOKUP($B25,TC_Fechas,TC_Venta_Rango,"",-1)="","",_xlfn.XLOOKUP($B25,TC_Fechas,TC_Venta_Rango,"",-1)),""))) | O25: =IF(OR($C25="",$N25=""),"",ROUND($J25*$N25,2)+ROUND($K25*$N25,2)) | P25: =IF($G25="","",IFERROR(INDEX(Catalogo_Tasas,MATCH($G25,Catalogo_Codigos,0)),"")) | Q25: =IF($G25="","",IFERROR(INDEX(Catalogo_Umbrales,MATCH($G25,Catalogo_Codigos,0)),"")) | R25: =IF(OR($C25="",$P25="",$O25=""),"",IF($F25<>"FACTURA","NO",IF(AND($P25>0,$O25>$Q25),"SI","NO"))) | S25: =IF($R25="SI",ROUND($O25*$P25,2),IF($C25="","",0)) | U25: =IF($C25="","",IF($R25<>"SI","",IF($T25="","SIN DATO",IF(ABS($T25-$S25)<=0.5,"OK","REVISAR")))) | W25: =IF(OR($C25="",$N25=""),"",IF($F25="RHE",ROUND($L25-$V25,2),ROUND($L25-($S25/$N25),2))) | AB25: PROVEEDOR
A26: 23 | B26: =DATE(2026,8,17) | C26: E001- 504 | D26: 10422800102 | E26: SARMIENTO LOPEZ LUIS RONALD | F26: RHE | G26: N/A | H26: =IF($G26="","",IFERROR(INDEX(Catalogo_Etiquetas,MATCH($G26,Catalogo_Codigos,0)),"CODIGO NO VALIDO")) | I26: USD | J26: 157 | K26: 0 | L26: =IF($C26="","",$J26+$K26) | M26: 632 | N26: =IF($C26="","",IF($I26="PEN",1,IFERROR(IF(_xlfn.XLOOKUP($B26,TC_Fechas,TC_Venta_Rango,"",-1)="","",_xlfn.XLOOKUP($B26,TC_Fechas,TC_Venta_Rango,"",-1)),""))) | O26: =IF(OR($C26="",$N26=""),"",ROUND($J26*$N26,2)+ROUND($K26*$N26,2)) | P26: =IF($G26="","",IFERROR(INDEX(Catalogo_Tasas,MATCH($G26,Catalogo_Codigos,0)),"")) | Q26: =IF($G26="","",IFERROR(INDEX(Catalogo_Umbrales,MATCH($G26,Catalogo_Codigos,0)),"")) | R26: =IF(OR($C26="",$P26="",$O26=""),"",IF($F26<>"FACTURA","NO",IF(AND($P26>0,$O26>$Q26),"SI","NO"))) | S26: =IF($R26="SI",ROUND($O26*$P26,2),IF($C26="","",0)) | U26: =IF($C26="","",IF($R26<>"SI","",IF($T26="","SIN DATO",IF(ABS($T26-$S26)<=0.5,"OK","REVISAR")))) | V26: 12.56 | W26: =IF(OR($C26="",$N26=""),"",IF($F26="RHE",ROUND($L26-$V26,2),ROUND($L26-($S26/$N26),2))) | AB26: PROVEEDOR
A27: 24 | B27: =DATE(2026,8,8) | C27: E001-1230 | D27: 20600179005 | E27: TRANSPORTES TURISTICOS LASER S.A.C. | F27: FACTURA | G27: 026 | H27: =IF($G27="","",IFERROR(INDEX(Catalogo_Etiquetas,MATCH($G27,Catalogo_Codigos,0)),"CODIGO NO VALIDO")) | I27: USD | J27: 1267.74 | K27: 228.19 | L27: =IF($C27="","",$J27+$K27) | M27: 631 | N27: =IF($C27="","",IF($I27="PEN",1,IFERROR(IF(_xlfn.XLOOKUP($B27,TC_Fechas,TC_Venta_Rango,"",-1)="","",_xlfn.XLOOKUP($B27,TC_Fechas,TC_Venta_Rango,"",-1)),""))) | O27: =IF(OR($C27="",$N27=""),"",ROUND($J27*$N27,2)+ROUND($K27*$N27,2)) | P27: =IF($G27="","",IFERROR(INDEX(Catalogo_Tasas,MATCH($G27,Catalogo_Codigos,0)),"")) | Q27: =IF($G27="","",IFERROR(INDEX(Catalogo_Umbrales,MATCH($G27,Catalogo_Codigos,0)),"")) | R27: =IF(OR($C27="",$P27="",$O27=""),"",IF($F27<>"FACTURA","NO",IF(AND($P27>0,$O27>$Q27),"SI","NO"))) | S27: =IF($R27="SI",ROUND($O27*$P27,2),IF($C27="","",0)) | T27: 508 | U27: =IF($C27="","",IF($R27<>"SI","",IF($T27="","SIN DATO",IF(ABS($T27-$S27)<=0.5,"OK","REVISAR")))) | W27: =IF(OR($C27="",$N27=""),"",IF($F27="RHE",ROUND($L27-$V27,2),ROUND($L27-($S27/$N27),2))) | AB27: PROVEEDOR
A28: 25 | B28: =DATE(2026,8,8) | C28: E001-1881 | D28: 20358309870 | E28: CAMPING TOURS E.I.R.LTDA | F28: FACTURA | G28: 037 | H28: =IF($G28="","",IFERROR(INDEX(Catalogo_Etiquetas,MATCH($G28,Catalogo_Codigos,0)),"CODIGO NO VALIDO")) | I28: USD | J28: 247.42 | K28: 44.53 | L28: =IF($C28="","",$J28+$K28) | M28: 639 | N28: =IF($C28="","",IF($I28="PEN",1,IFERROR(IF(_xlfn.XLOOKUP($B28,TC_Fechas,TC_Venta_Rango,"",-1)="","",_xlfn.XLOOKUP($B28,TC_Fechas,TC_Venta_Rango,"",-1)),""))) | O28: =IF(OR($C28="",$N28=""),"",ROUND($J28*$N28,2)+ROUND($K28*$N28,2)) | P28: =IF($G28="","",IFERROR(INDEX(Catalogo_Tasas,MATCH($G28,Catalogo_Codigos,0)),"")) | Q28: =IF($G28="","",IFERROR(INDEX(Catalogo_Umbrales,MATCH($G28,Catalogo_Codigos,0)),"")) | R28: =IF(OR($C28="",$P28="",$O28=""),"",IF($F28<>"FACTURA","NO",IF(AND($P28>0,$O28>$Q28),"SI","NO"))) | S28: =IF($R28="SI",ROUND($O28*$P28,2),IF($C28="","",0)) | T28: 118.8 | U28: =IF($C28="","",IF($R28<>"SI","",IF($T28="","SIN DATO",IF(ABS($T28-$S28)<=0.5,"OK","REVISAR")))) | W28: =IF(OR($C28="",$N28=""),"",IF($F28="RHE",ROUND($L28-$V28,2),ROUND($L28-($S28/$N28),2))) | AB28: PROVEEDOR
A29: 26 | B29: =DATE(2026,8,18) | C29: F078-00047775 | D29: 20505670443 | E29: NESSUS HOTELES PERU S.A. (Casa Andina Select Arequipa) | F29: FACTURA | G29: N/A | H29: =IF($G29="","",IFERROR(INDEX(Catalogo_Etiquetas,MATCH($G29,Catalogo_Codigos,0)),"CODIGO NO VALIDO")) | I29: USD | J29: 274 | K29: 0 | L29: =IF($C29="","",$J29+$K29) | M29: 639 | N29: =IF($C29="","",IF($I29="PEN",1,IFERROR(IF(_xlfn.XLOOKUP($B29,TC_Fechas,TC_Venta_Rango,"",-1)="","",_xlfn.XLOOKUP($B29,TC_Fechas,TC_Venta_Rango,"",-1)),""))) | O29: =IF(OR($C29="",$N29=""),"",ROUND($J29*$N29,2)+ROUND($K29*$N29,2)) | P29: =IF($G29="","",IFERROR(INDEX(Catalogo_Tasas,MATCH($G29,Catalogo_Codigos,0)),"")) | Q29: =IF($G29="","",IFERROR(INDEX(Catalogo_Umbrales,MATCH($G29,Catalogo_Codigos,0)),"")) | R29: =IF(OR($C29="",$P29="",$O29=""),"",IF($F29<>"FACTURA","NO",IF(AND($P29>0,$O29>$Q29),"SI","NO"))) | S29: =IF($R29="SI",ROUND($O29*$P29,2),IF($C29="","",0)) | U29: =IF($C29="","",IF($R29<>"SI","",IF($T29="","SIN DATO",IF(ABS($T29-$S29)<=0.5,"OK","REVISAR")))) | W29: =IF(OR($C29="",$N29=""),"",IF($F29="RHE",ROUND($L29-$V29,2),ROUND($L29-($S29/$N29),2))) | AB29: PROVEEDOR
A30: 27 | B30: =DATE(2026,8,6) | C30: E001-327 | D30: 20603668406 | E30: LUXURY ADVENTURE CUSCO PERU E.I.R.L. | F30: FACTURA | G30: N/A | H30: =IF($G30="","",IFERROR(INDEX(Catalogo_Etiquetas,MATCH($G30,Catalogo_Codigos,0)),"CODIGO NO VALIDO")) | I30: USD | J30: 88.98 | K30: 16.02 | L30: =IF($C30="","",$J30+$K30) | M30: 639 | N30: =IF($C30="","",IF($I30="PEN",1,IFERROR(IF(_xlfn.XLOOKUP($B30,TC_Fechas,TC_Venta_Rango,"",-1)="","",_xlfn.XLOOKUP($B30,TC_Fechas,TC_Venta_Rango,"",-1)),""))) | O30: =IF(OR($C30="",$N30=""),"",ROUND($J30*$N30,2)+ROUND($K30*$N30,2)) | P30: =IF($G30="","",IFERROR(INDEX(Catalogo_Tasas,MATCH($G30,Catalogo_Codigos,0)),"")) | Q30: =IF($G30="","",IFERROR(INDEX(Catalogo_Umbrales,MATCH($G30,Catalogo_Codigos,0)),"")) | R30: =IF(OR($C30="",$P30="",$O30=""),"",IF($F30<>"FACTURA","NO",IF(AND($P30>0,$O30>$Q30),"SI","NO"))) | S30: =IF($R30="SI",ROUND($O30*$P30,2),IF($C30="","",0)) | U30: =IF($C30="","",IF($R30<>"SI","",IF($T30="","SIN DATO",IF(ABS($T30-$S30)<=0.5,"OK","REVISAR")))) | W30: =IF(OR($C30="",$N30=""),"",IF($F30="RHE",ROUND($L30-$V30,2),ROUND($L30-($S30/$N30),2))) | AB30: PROVEEDOR
A31: 28 | B31: =DATE(2026,8,6) | C31: E001-332 | D31: 20603668406 | E31: LUXURY ADVENTURE CUSCO PERU E.I.R.L. | F31: FACTURA | G31: N/A | H31: =IF($G31="","",IFERROR(INDEX(Catalogo_Etiquetas,MATCH($G31,Catalogo_Codigos,0)),"CODIGO NO VALIDO")) | I31: USD | J31: 103.81 | K31: 18.69 | L31: =IF($C31="","",$J31+$K31) | M31: 639 | N31: =IF($C31="","",IF($I31="PEN",1,IFERROR(IF(_xlfn.XLOOKUP($B31,TC_Fechas,TC_Venta_Rango,"",-1)="","",_xlfn.XLOOKUP($B31,TC_Fechas,TC_Venta_Rango,"",-1)),""))) | O31: =IF(OR($C31="",$N31=""),"",ROUND($J31*$N31,2)+ROUND($K31*$N31,2)) | P31: =IF($G31="","",IFERROR(INDEX(Catalogo_Tasas,MATCH($G31,Catalogo_Codigos,0)),"")) | Q31: =IF($G31="","",IFERROR(INDEX(Catalogo_Umbrales,MATCH($G31,Catalogo_Codigos,0)),"")) | R31: =IF(OR($C31="",$P31="",$O31=""),"",IF($F31<>"FACTURA","NO",IF(AND($P31>0,$O31>$Q31),"SI","NO"))) | S31: =IF($R31="SI",ROUND($O31*$P31,2),IF($C31="","",0)) | U31: =IF($C31="","",IF($R31<>"SI","",IF($T31="","SIN DATO",IF(ABS($T31-$S31)<=0.5,"OK","REVISAR")))) | W31: =IF(OR($C31="",$N31=""),"",IF($F31="RHE",ROUND($L31-$V31,2),ROUND($L31-($S31/$N31),2))) | AB31: PROVEEDOR
A32: 29 | B32: =DATE(2026,8,19) | C32: F011-30391 | D32: 20442088811 | E32: ALBERGUE OLLANTAYTAMBO EIRL | F32: FACTURA | G32: N/A | H32: =IF($G32="","",IFERROR(INDEX(Catalogo_Etiquetas,MATCH($G32,Catalogo_Codigos,0)),"CODIGO NO VALIDO")) | I32: USD | J32: 89.06 | K32: 16.03 | L32: =IF($C32="","",$J32+$K32) | M32: 639 | N32: =IF($C32="","",IF($I32="PEN",1,IFERROR(IF(_xlfn.XLOOKUP($B32,TC_Fechas,TC_Venta_Rango,"",-1)="","",_xlfn.XLOOKUP($B32,TC_Fechas,TC_Venta_Rango,"",-1)),""))) | O32: =IF(OR($C32="",$N32=""),"",ROUND($J32*$N32,2)+ROUND($K32*$N32,2)) | P32: =IF($G32="","",IFERROR(INDEX(Catalogo_Tasas,MATCH($G32,Catalogo_Codigos,0)),"")) | Q32: =IF($G32="","",IFERROR(INDEX(Catalogo_Umbrales,MATCH($G32,Catalogo_Codigos,0)),"")) | R32: =IF(OR($C32="",$P32="",$O32=""),"",IF($F32<>"FACTURA","NO",IF(AND($P32>0,$O32>$Q32),"SI","NO"))) | S32: =IF($R32="SI",ROUND($O32*$P32,2),IF($C32="","",0)) | U32: =IF($C32="","",IF($R32<>"SI","",IF($T32="","SIN DATO",IF(ABS($T32-$S32)<=0.5,"OK","REVISAR")))) | W32: =IF(OR($C32="",$N32=""),"",IF($F32="RHE",ROUND($L32-$V32,2),ROUND($L32-($S32/$N32),2))) | AB32: PROVEEDOR
A33: 30 | B33: =DATE(2026,8,5) | C33: E001- 468 | D33: 10448269201 | E33: ANCAYPURO TORRES JOSE LUIS | F33: RHE | G33: N/A | H33: =IF($G33="","",IFERROR(INDEX(Catalogo_Etiquetas,MATCH($G33,Catalogo_Codigos,0)),"CODIGO NO VALIDO")) | I33: PEN | J33: 40 | K33: 0 | L33: =IF($C33="","",$J33+$K33) | M33: 632 | N33: =IF($C33="","",IF($I33="PEN",1,IFERROR(IF(_xlfn.XLOOKUP($B33,TC_Fechas,TC_Venta_Rango,"",-1)="","",_xlfn.XLOOKUP($B33,TC_Fechas,TC_Venta_Rango,"",-1)),""))) | O33: =IF(OR($C33="",$N33=""),"",ROUND($J33*$N33,2)+ROUND($K33*$N33,2)) | P33: =IF($G33="","",IFERROR(INDEX(Catalogo_Tasas,MATCH($G33,Catalogo_Codigos,0)),"")) | Q33: =IF($G33="","",IFERROR(INDEX(Catalogo_Umbrales,MATCH($G33,Catalogo_Codigos,0)),"")) | R33: =IF(OR($C33="",$P33="",$O33=""),"",IF($F33<>"FACTURA","NO",IF(AND($P33>0,$O33>$Q33),"SI","NO"))) | S33: =IF($R33="SI",ROUND($O33*$P33,2),IF($C33="","",0)) | U33: =IF($C33="","",IF($R33<>"SI","",IF($T33="","SIN DATO",IF(ABS($T33-$S33)<=0.5,"OK","REVISAR")))) | W33: =IF(OR($C33="",$N33=""),"",IF($F33="RHE",ROUND($L33-$V33,2),ROUND($L33-($S33/$N33),2))) | AB33: PROVEEDOR
A34: 31 | B34: =DATE(2026,8,10) | C34: E001- 174 | D34: 10408744151 | E34: BEOUTIS BAZAN URSULA CATHERINE | F34: RHE | G34: N/A | H34: =IF($G34="","",IFERROR(INDEX(Catalogo_Etiquetas,MATCH($G34,Catalogo_Codigos,0)),"CODIGO NO VALIDO")) | I34: PEN | J34: 1025 | K34: 0 | L34: =IF($C34="","",$J34+$K34) | M34: 632 | N34: =IF($C34="","",IF($I34="PEN",1,IFERROR(IF(_xlfn.XLOOKUP($B34,TC_Fechas,TC_Venta_Rango,"",-1)="","",_xlfn.XLOOKUP($B34,TC_Fechas,TC_Venta_Rango,"",-1)),""))) | O34: =IF(OR($C34="",$N34=""),"",ROUND($J34*$N34,2)+ROUND($K34*$N34,2)) | P34: =IF($G34="","",IFERROR(INDEX(Catalogo_Tasas,MATCH($G34,Catalogo_Codigos,0)),"")) | Q34: =IF($G34="","",IFERROR(INDEX(Catalogo_Umbrales,MATCH($G34,Catalogo_Codigos,0)),"")) | R34: =IF(OR($C34="",$P34="",$O34=""),"",IF($F34<>"FACTURA","NO",IF(AND($P34>0,$O34>$Q34),"SI","NO"))) | S34: =IF($R34="SI",ROUND($O34*$P34,2),IF($C34="","",0)) | U34: =IF($C34="","",IF($R34<>"SI","",IF($T34="","SIN DATO",IF(ABS($T34-$S34)<=0.5,"OK","REVISAR")))) | W34: =IF(OR($C34="",$N34=""),"",IF($F34="RHE",ROUND($L34-$V34,2),ROUND($L34-($S34/$N34),2))) | AB34: ADMINISTRATIVO
A35: 32 | B35: =DATE(2026,8,18) | C35: E001- 546 | D35: 10408222490 | E35: CARRASCO ALEGRE ROLLY VICTOR | F35: RHE | G35: N/A | H35: =IF($G35="","",IFERROR(INDEX(Catalogo_Etiquetas,MATCH($G35,Catalogo_Codigos,0)),"CODIGO NO VALIDO")) | I35: USD | J35: 60 | K35: 0 | L35: =IF($C35="","",$J35+$K35) | M35: 632 | N35: =IF($C35="","",IF($I35="PEN",1,IFERROR(IF(_xlfn.XLOOKUP($B35,TC_Fechas,TC_Venta_Rango,"",-1)="","",_xlfn.XLOOKUP($B35,TC_Fechas,TC_Venta_Rango,"",-1)),""))) | O35: =IF(OR($C35="",$N35=""),"",ROUND($J35*$N35,2)+ROUND($K35*$N35,2)) | P35: =IF($G35="","",IFERROR(INDEX(Catalogo_Tasas,MATCH($G35,Catalogo_Codigos,0)),"")) | Q35: =IF($G35="","",IFERROR(INDEX(Catalogo_Umbrales,MATCH($G35,Catalogo_Codigos,0)),"")) | R35: =IF(OR($C35="",$P35="",$O35=""),"",IF($F35<>"FACTURA","NO",IF(AND($P35>0,$O35>$Q35),"SI","NO"))) | S35: =IF($R35="SI",ROUND($O35*$P35,2),IF($C35="","",0)) | U35: =IF($C35="","",IF($R35<>"SI","",IF($T35="","SIN DATO",IF(ABS($T35-$S35)<=0.5,"OK","REVISAR")))) | W35: =IF(OR($C35="",$N35=""),"",IF($F35="RHE",ROUND($L35-$V35,2),ROUND($L35-($S35/$N35),2))) | AB35: PROVEEDOR
A36: 33 | B36: =DATE(2026,8,14) | C36: FA02-00001856 | D36: 20527992525 | E36: CUSCO RESTAURANTS S.A.C. | F36: FACTURA | G36: N/A | H36: =IF($G36="","",IFERROR(INDEX(Catalogo_Etiquetas,MATCH($G36,Catalogo_Codigos,0)),"CODIGO NO VALIDO")) | I36: USD | J36: 54.69 | K36: 9.84 | L36: =IF($C36="","",$J36+$K36) | M36: 639 | N36: =IF($C36="","",IF($I36="PEN",1,IFERROR(IF(_xlfn.XLOOKUP($B36,TC_Fechas,TC_Venta_Rango,"",-1)="","",_xlfn.XLOOKUP($B36,TC_Fechas,TC_Venta_Rango,"",-1)),""))) | O36: =IF(OR($C36="",$N36=""),"",ROUND($J36*$N36,2)+ROUND($K36*$N36,2)) | P36: =IF($G36="","",IFERROR(INDEX(Catalogo_Tasas,MATCH($G36,Catalogo_Codigos,0)),"")) | Q36: =IF($G36="","",IFERROR(INDEX(Catalogo_Umbrales,MATCH($G36,Catalogo_Codigos,0)),"")) | R36: =IF(OR($C36="",$P36="",$O36=""),"",IF($F36<>"FACTURA","NO",IF(AND($P36>0,$O36>$Q36),"SI","NO"))) | S36: =IF($R36="SI",ROUND($O36*$P36,2),IF($C36="","",0)) | U36: =IF($C36="","",IF($R36<>"SI","",IF($T36="","SIN DATO",IF(ABS($T36-$S36)<=0.5,"OK","REVISAR")))) | W36: =IF(OR($C36="",$N36=""),"",IF($F36="RHE",ROUND($L36-$V36,2),ROUND($L36-($S36/$N36),2))) | AB36: PROVEEDOR
A37: 34 | B37: =DATE(2026,8,14) | C37: F005-019033 | D37: 20252796623 | E37: GRESCO S.A.C. | F37: FACTURA | G37: N/A | H37: =IF($G37="","",IFERROR(INDEX(Catalogo_Etiquetas,MATCH($G37,Catalogo_Codigos,0)),"CODIGO NO VALIDO")) | I37: PEN | J37: 630.56 | K37: 113.5 | L37: =IF($C37="","",$J37+$K37) | M37: 639 | N37: =IF($C37="","",IF($I37="PEN",1,IFERROR(IF(_xlfn.XLOOKUP($B37,TC_Fechas,TC_Venta_Rango,"",-1)="","",_xlfn.XLOOKUP($B37,TC_Fechas,TC_Venta_Rango,"",-1)),""))) | O37: =IF(OR($C37="",$N37=""),"",ROUND($J37*$N37,2)+ROUND($K37*$N37,2)) | P37: =IF($G37="","",IFERROR(INDEX(Catalogo_Tasas,MATCH($G37,Catalogo_Codigos,0)),"")) | Q37: =IF($G37="","",IFERROR(INDEX(Catalogo_Umbrales,MATCH($G37,Catalogo_Codigos,0)),"")) | R37: =IF(OR($C37="",$P37="",$O37=""),"",IF($F37<>"FACTURA","NO",IF(AND($P37>0,$O37>$Q37),"SI","NO"))) | S37: =IF($R37="SI",ROUND($O37*$P37,2),IF($C37="","",0)) | U37: =IF($C37="","",IF($R37<>"SI","",IF($T37="","SIN DATO",IF(ABS($T37-$S37)<=0.5,"OK","REVISAR")))) | W37: =IF(OR($C37="",$N37=""),"",IF($F37="RHE",ROUND($L37-$V37,2),ROUND($L37-($S37/$N37),2))) | AB37: PROVEEDOR
A38: 35 | B38: =DATE(2026,8,13) | C38: F008-00035633 | D38: 20536047906 | E38: HOTELERIA PERUANA S.A.C. (TIERRA VIVA HOTELS) | F38: FACTURA | G38: N/A | H38: =IF($G38="","",IFERROR(INDEX(Catalogo_Etiquetas,MATCH($G38,Catalogo_Codigos,0)),"CODIGO NO VALIDO")) | I38: USD | J38: 138.18 | K38: 0 | L38: =IF($C38="","",$J38+$K38) | M38: 639 | N38: =IF($C38="","",IF($I38="PEN",1,IFERROR(IF(_xlfn.XLOOKUP($B38,TC_Fechas,TC_Venta_Rango,"",-1)="","",_xlfn.XLOOKUP($B38,TC_Fechas,TC_Venta_Rango,"",-1)),""))) | O38: =IF(OR($C38="",$N38=""),"",ROUND($J38*$N38,2)+ROUND($K38*$N38,2)) | P38: =IF($G38="","",IFERROR(INDEX(Catalogo_Tasas,MATCH($G38,Catalogo_Codigos,0)),"")) | Q38: =IF($G38="","",IFERROR(INDEX(Catalogo_Umbrales,MATCH($G38,Catalogo_Codigos,0)),"")) | R38: =IF(OR($C38="",$P38="",$O38=""),"",IF($F38<>"FACTURA","NO",IF(AND($P38>0,$O38>$Q38),"SI","NO"))) | S38: =IF($R38="SI",ROUND($O38*$P38,2),IF($C38="","",0)) | U38: =IF($C38="","",IF($R38<>"SI","",IF($T38="","SIN DATO",IF(ABS($T38-$S38)<=0.5,"OK","REVISAR")))) | W38: =IF(OR($C38="",$N38=""),"",IF($F38="RHE",ROUND($L38-$V38,2),ROUND($L38-($S38/$N38),2))) | AB38: PROVEEDOR
A39: 36 | B39: =DATE(2026,8,17) | C39: F006-00003185 | D39: 20610235736 | E39: HOTELES LA HACIENDA S.A.C. | F39: FACTURA | G39: N/A | H39: =IF($G39="","",IFERROR(INDEX(Catalogo_Etiquetas,MATCH($G39,Catalogo_Codigos,0)),"CODIGO NO VALIDO")) | I39: USD | J39: 318.58 | K39: 0 | L39: =IF($C39="","",$J39+$K39) | M39: 639 | N39: =IF($C39="","",IF($I39="PEN",1,IFERROR(IF(_xlfn.XLOOKUP($B39,TC_Fechas,TC_Venta_Rango,"",-1)="","",_xlfn.XLOOKUP($B39,TC_Fechas,TC_Venta_Rango,"",-1)),""))) | O39: =IF(OR($C39="",$N39=""),"",ROUND($J39*$N39,2)+ROUND($K39*$N39,2)) | P39: =IF($G39="","",IFERROR(INDEX(Catalogo_Tasas,MATCH($G39,Catalogo_Codigos,0)),"")) | Q39: =IF($G39="","",IFERROR(INDEX(Catalogo_Umbrales,MATCH($G39,Catalogo_Codigos,0)),"")) | R39: =IF(OR($C39="",$P39="",$O39=""),"",IF($F39<>"FACTURA","NO",IF(AND($P39>0,$O39>$Q39),"SI","NO"))) | S39: =IF($R39="SI",ROUND($O39*$P39,2),IF($C39="","",0)) | U39: =IF($C39="","",IF($R39<>"SI","",IF($T39="","SIN DATO",IF(ABS($T39-$S39)<=0.5,"OK","REVISAR")))) | W39: =IF(OR($C39="",$N39=""),"",IF($F39="RHE",ROUND($L39-$V39,2),ROUND($L39-($S39/$N39),2))) | AB39: PROVEEDOR
A40: 37 | B40: =DATE(2026,8,18) | C40: F302-00029273 | D40: 20114803228 | E40: INVERSIONES NACIONALES DE TURISMO S.A. (Palacio del Inka Hotel) | F40: FACTURA | G40: N/A | H40: =IF($G40="","",IFERROR(INDEX(Catalogo_Etiquetas,MATCH($G40,Catalogo_Codigos,0)),"CODIGO NO VALIDO")) | I40: USD | J40: 1102 | K40: 0 | L40: =IF($C40="","",$J40+$K40) | M40: 639 | N40: =IF($C40="","",IF($I40="PEN",1,IFERROR(IF(_xlfn.XLOOKUP($B40,TC_Fechas,TC_Venta_Rango,"",-1)="","",_xlfn.XLOOKUP($B40,TC_Fechas,TC_Venta_Rango,"",-1)),""))) | O40: =IF(OR($C40="",$N40=""),"",ROUND($J40*$N40,2)+ROUND($K40*$N40,2)) | P40: =IF($G40="","",IFERROR(INDEX(Catalogo_Tasas,MATCH($G40,Catalogo_Codigos,0)),"")) | Q40: =IF($G40="","",IFERROR(INDEX(Catalogo_Umbrales,MATCH($G40,Catalogo_Codigos,0)),"")) | R40: =IF(OR($C40="",$P40="",$O40=""),"",IF($F40<>"FACTURA","NO",IF(AND($P40>0,$O40>$Q40),"SI","NO"))) | S40: =IF($R40="SI",ROUND($O40*$P40,2),IF($C40="","",0)) | U40: =IF($C40="","",IF($R40<>"SI","",IF($T40="","SIN DATO",IF(ABS($T40-$S40)<=0.5,"OK","REVISAR")))) | W40: =IF(OR($C40="",$N40=""),"",IF($F40="RHE",ROUND($L40-$V40,2),ROUND($L40-($S40/$N40),2))) | AB40: PROVEEDOR
...

Sheet Registro_Ventas
A1: Registro de Ventas — Comprobantes Emitidos a Clientes
A2: Caso normal: "¿Sujeto a Detracción Emitida?" = NO (Braidy Wonders casi siempre es el adquiriente, no el emisor, de servicios del Anexo 3). Marca SI solo si el servicio que facturas está en el catálogo (ej. transporte de personas).
A3: N° | B3: Fecha Emisión | C3: N° Comprobante | D3: RUC/Doc. Cliente | E3: Cliente | F3: Moneda | G3: Valor Venta | H3: IGV (18%) | I3: Total Factura | J3: ¿Sujeto a Detracción Emitida? | K3: Concepto (si aplica, elige de la lista) | L3: % Detracción | M3: Monto Detracción | N3: Neto a Cobrar | O3: ¿Cobrado? | P3: Fecha de Cobro | Q3: Estado | R3: ¿Exportación de Servicios Turísticos (No Domiciliado)?
A4: 1 | B4: 2026-08-10 | C4: F001-EJEMPLO | D4: 10999999999 | E4: Cliente de Ejemplo [BORRAR/REEMPLAZAR] | F4: USD | G4: 2000 | H4: =IF(C4="","",IF(R4="SI",0,G4*0.18)) | I4: =IF(C4="","",G4+H4) | J4: NO | L4: =IF(OR(C4="",J4<>"SI",K4=""),IF(C4="","",0),IFERROR(INDEX(Catalogo_Tasas,MATCH(K4,Catalogo_Etiquetas,0)),0)) | M4: =IF(C4="","",IF(J4="SI",ROUND(I4*L4,2),0)) | N4: =IF(C4="","",I4-M4) | O4: SI | P4: 2026-08-20 | Q4: EJEMPLO | R4: SI
A5: 2 | H5: =IF(C5="","",IF(R5="SI",0,G5*0.18)) | I5: =IF(C5="","",G5+H5) | L5: =IF(OR(C5="",J5<>"SI",K5=""),IF(C5="","",0),IFERROR(INDEX(Catalogo_Tasas,MATCH(K5,Catalogo_Etiquetas,0)),0)) | M5: =IF(C5="","",IF(J5="SI",ROUND(I5*L5,2),0)) | N5: =IF(C5="","",I5-M5)
A6: 3 | H6: =IF(C6="","",IF(R6="SI",0,G6*0.18)) | I6: =IF(C6="","",G6+H6) | L6: =IF(OR(C6="",J6<>"SI",K6=""),IF(C6="","",0),IFERROR(INDEX(Catalogo_Tasas,MATCH(K6,Catalogo_Etiquetas,0)),0)) | M6: =IF(C6="","",IF(J6="SI",ROUND(I6*L6,2),0)) | N6: =IF(C6="","",I6-M6)
A7: 4 | H7: =IF(C7="","",IF(R7="SI",0,G7*0.18)) | I7: =IF(C7="","",G7+H7) | L7: =IF(OR(C7="",J7<>"SI",K7=""),IF(C7="","",0),IFERROR(INDEX(Catalogo_Tasas,MATCH(K7,Catalogo_Etiquetas,0)),0)) | M7: =IF(C7="","",IF(J7="SI",ROUND(I7*L7,2),0)) | N7: =IF(C7="","",I7-M7)
A8: 5 | H8: =IF(C8="","",IF(R8="SI",0,G8*0.18)) | I8: =IF(C8="","",G8+H8) | L8: =IF(OR(C8="",J8<>"SI",K8=""),IF(C8="","",0),IFERROR(INDEX(Catalogo_Tasas,MATCH(K8,Catalogo_Etiquetas,0)),0)) | M8: =IF(C8="","",IF(J8="SI",ROUND(I8*L8,2),0)) | N8: =IF(C8="","",I8-M8)
A9: 6 | H9: =IF(C9="","",IF(R9="SI",0,G9*0.18)) | I9: =IF(C9="","",G9+H9) | L9: =IF(OR(C9="",J9<>"SI",K9=""),IF(C9="","",0),IFERROR(INDEX(Catalogo_Tasas,MATCH(K9,Catalogo_Etiquetas,0)),0)) | M9: =IF(C9="","",IF(J9="SI",ROUND(I9*L9,2),0)) | N9: =IF(C9="","",I9-M9)
A10: 7 | H10: =IF(C10="","",IF(R10="SI",0,G10*0.18)) | I10: =IF(C10="","",G10+H10) | L10: =IF(OR(C10="",J10<>"SI",K10=""),IF(C10="","",0),IFERROR(INDEX(Catalogo_Tasas,MATCH(K10,Catalogo_Etiquetas,0)),0)) | M10: =IF(C10="","",IF(J10="SI",ROUND(I10*L10,2),0)) | N10: =IF(C10="","",I10-M10)
A11: 8 | H11: =IF(C11="","",IF(R11="SI",0,G11*0.18)) | I11: =IF(C11="","",G11+H11) | L11: =IF(OR(C11="",J11<>"SI",K11=""),IF(C11="","",0),IFERROR(INDEX(Catalogo_Tasas,MATCH(K11,Catalogo_Etiquetas,0)),0)) | M11: =IF(C11="","",IF(J11="SI",ROUND(I11*L11,2),0)) | N11: =IF(C11="","",I11-M11)
A12: 9 | H12: =IF(C12="","",IF(R12="SI",0,G12*0.18)) | I12: =IF(C12="","",G12+H12) | L12: =IF(OR(C12="",J12<>"SI",K12=""),IF(C12="","",0),IFERROR(INDEX(Catalogo_Tasas,MATCH(K12,Catalogo_Etiquetas,0)),0)) | M12: =IF(C12="","",IF(J12="SI",ROUND(I12*L12,2),0)) | N12: =IF(C12="","",I12-M12)
A13: 10 | H13: =IF(C13="","",IF(R13="SI",0,G13*0.18)) | I13: =IF(C13="","",G13+H13) | L13: =IF(OR(C13="",J13<>"SI",K13=""),IF(C13="","",0),IFERROR(INDEX(Catalogo_Tasas,MATCH(K13,Catalogo_Etiquetas,0)),0)) | M13: =IF(C13="","",IF(J13="SI",ROUND(I13*L13,2),0)) | N13: =IF(C13="","",I13-M13)
A14: 11 | H14: =IF(C14="","",IF(R14="SI",0,G14*0.18)) | I14: =IF(C14="","",G14+H14) | L14: =IF(OR(C14="",J14<>"SI",K14=""),IF(C14="","",0),IFERROR(INDEX(Catalogo_Tasas,MATCH(K14,Catalogo_Etiquetas,0)),0)) | M14: =IF(C14="","",IF(J14="SI",ROUND(I14*L14,2),0)) | N14: =IF(C14="","",I14-M14)
A15: 12 | H15: =IF(C15="","",IF(R15="SI",0,G15*0.18)) | I15: =IF(C15="","",G15+H15) | L15: =IF(OR(C15="",J15<>"SI",K15=""),IF(C15="","",0),IFERROR(INDEX(Catalogo_Tasas,MATCH(K15,Catalogo_Etiquetas,0)),0)) | M15: =IF(C15="","",IF(J15="SI",ROUND(I15*L15,2),0)) | N15: =IF(C15="","",I15-M15)
A16: 13 | H16: =IF(C16="","",IF(R16="SI",0,G16*0.18)) | I16: =IF(C16="","",G16+H16) | L16: =IF(OR(C16="",J16<>"SI",K16=""),IF(C16="","",0),IFERROR(INDEX(Catalogo_Tasas,MATCH(K16,Catalogo_Etiquetas,0)),0)) | M16: =IF(C16="","",IF(J16="SI",ROUND(I16*L16,2),0)) | N16: =IF(C16="","",I16-M16)
... A53: 50 | H53: =IF(C53="","",IF(R53="SI",0,G53*0.18)) | I53: =IF(C53="","",G53+H53) | L53: =IF(OR(C53="",J53<>"SI",K53=""),IF(C53="","",0),IFERROR(INDEX(Catalogo_Tasas,MATCH(K53,Catalogo_Etiquetas,0)),0)) | M53: =IF(C53="","",IF(J53="SI",ROUND(I53*L53,2),0)) | N53: =IF(C53="","",I53-M53)

Sheet Libro_Diario
A1: Libro Diario - Braidy Wonders SAC
A2: Se genera solo desde Registro_Compras y Registro_Ventas. No editar a mano. Importes en PEN. Los asientos de deposito de detraccion y de pago del neto solo aparecen cuando la fecha real correspondiente esta cargada en el registro de origen.
A3: Fecha | B3: N° Asiento | C3: Cuenta | D3: Denominación | E3: Debe | F3: Haber | G3: Glosa | H3: Ref. Comprobante
A4: COMPRAS - Facturas de Proveedores
A5: =IF($C5="","",Registro_Compras!$B$4) | B5: =IF($C5="","","C"&TEXT(INT((ROW()-5)/9)+1,"000")&"-1") | C5: =IF(OR(Registro_Compras!$C$4="",Registro_Compras!$O$4=""),"",IF(Registro_Compras!$F$4="NOTA DE CREDITO","4212",IF(Registro_Compras!$M$4="","63",Registro_Compras!$M$4))) | D5: =IF(OR(Registro_Compras!$C$4="",Registro_Compras!$O$4=""),"",IF(Registro_Compras!$F$4="NOTA DE CREDITO","Cuentas por Pagar Comerciales - Terceros (Emitidas)",IF(Registro_Compras!$F$4="RHE","Honorarios Profesionales - Servicios de Terceros","Gastos de Servicios Prestados por Terceros"))) | E5: =IF($C5="","",IF(Registro_Compras!$F$4="NOTA DE CREDITO",ABS(Registro_Compras!$O$4),IF(Registro_Compras!$F$4="RHE",ROUND(Registro_Compras!$L$4*Registro_Compras!$N$4,2),ROUND(Registro_Compras!$J$4*Registro_Compras!$N$4,2)))) | F5: ="" | G5: =IF($C5="","",IF(Registro_Compras!$F$4="NOTA DE CREDITO","Por la nota de credito "&Registro_Compras!$C$4&" de "&Registro_Compras!$E$4&" [PATRON POR CONFIRMAR CON CONTADOR]",IF(Registro_Compras!$F$4="RHE","Por el registro del recibo por honorarios "&Registro_Compras!$C$4&" de "&Registro_Compras!$E$4&" [PATRON POR CONFIRMAR CON CONTADOR]","Por el registro de la factura "&Registro_Compras!$C$4&" de "&Registro_Compras!$E$4))) | H5: =IF($C5="","",Registro_Compras!$C$4)
A6: =IF($C6="","",Registro_Compras!$B$4) | B6: =IF($C6="","","C"&TEXT(INT((ROW()-5)/9)+1,"000")&"-1") | C6: =IF(OR(Registro_Compras!$C$4="",Registro_Compras!$O$4=""),"",IF(Registro_Compras!$F$4="RHE",IF(Registro_Compras!$V$4=0,"","40172"),IF(Registro_Compras!$F$4="NOTA DE CREDITO",IF(Registro_Compras!$M$4="","63",Registro_Compras!$M$4),IF(Registro_Compras!$K$4=0,"","40111")))) | D6: =IF(OR(Registro_Compras!$C$4="",Registro_Compras!$O$4=""),"",IF(Registro_Compras!$F$4="RHE","Retencion Renta 4ta Categoria por Pagar",IF(Registro_Compras!$F$4="NOTA DE CREDITO","Gastos de Servicios Prestados por Terceros","IGV - Cuenta Propia (Credito Fiscal)"))) | E6: =IF($C6="","",IF(Registro_Compras!$F$4="FACTURA",ROUND(Registro_Compras!$K$4*Registro_Compras!$N$4,2),"")) | F6: =IF($C6="","",IF(Registro_Compras!$F$4="RHE",ROUND(Registro_Compras!$V$4*Registro_Compras!$N$4,2),IF(Registro_Compras!$F$4="NOTA DE CREDITO",ROUND(ABS(Registro_Compras!$J$4*Registro_Compras!$N$4),2),""))) | G6: =IF($C6="","",IF(Registro_Compras!$F$4="NOTA DE CREDITO","Por la nota de credito "&Registro_Compras!$C$4&" de "&Registro_Compras!$E$4&" [PATRON POR CONFIRMAR CON CONTADOR]",IF(Registro_Compras!$F$4="RHE","Por el registro del recibo por honorarios "&Registro_Compras!$C$4&" de "&Registro_Compras!$E$4&" [PATRON POR CONFIRMAR CON CONTADOR]","Por el registro de la factura "&Registro_Compras!$C$4&" de "&Registro_Compras!$E$4))) | H6: =IF($C6="","",Registro_Compras!$C$4)
A7: =IF($C7="","",Registro_Compras!$B$4) | B7: =IF($C7="","","C"&TEXT(INT((ROW()-5)/9)+1,"000")&"-1") | C7: =IF(OR(Registro_Compras!$C$4="",Registro_Compras!$O$4=""),"",IF(Registro_Compras!$F$4="NOTA DE CREDITO",IF(Registro_Compras!$K$4=0,"","40111"),"4212")) | D7: =IF(OR(Registro_Compras!$C$4="",Registro_Compras!$O$4=""),"",IF(Registro_Compras!$F$4="NOTA DE CREDITO","IGV - Cuenta Propia (Credito Fiscal)","Cuentas por Pagar Comerciales - Terceros (Emitidas)")) | E7: ="" | F7: =IF($C7="","",IF(Registro_Compras!$F$4="NOTA DE CREDITO",ROUND(ABS(Registro_Compras!$K$4*Registro_Compras!$N$4),2),IF(Registro_Compras!$F$4="RHE",(ROUND(Registro_Compras!$L$4*Registro_Compras!$N$4,2)-ROUND(Registro_Compras!$V$4*Registro_Compras!$N$4,2)),Registro_Compras!$O$4))) | G7: =IF($C7="","",IF(Registro_Compras!$F$4="NOTA DE CREDITO","Por la nota de credito "&Registro_Compras!$C$4&" de "&Registro_Compras!$E$4&" [PATRON POR CONFIRMAR CON CONTADOR]",IF(Registro_Compras!$F$4="RHE","Por el registro del recibo por honorarios "&Registro_Compras!$C$4&" de "&Registro_Compras!$E$4&" [PATRON POR CONFIRMAR CON CONTADOR]","Por el registro de la factura "&Registro_Compras!$C$4&" de "&Registro_Compras!$E$4))) | H7: =IF($C7="","",Registro_Compras!$C$4)
A8: =IF($C8="","",Registro_Compras!$B$4) | B8: =IF($C8="","","C"&TEXT(INT((ROW()-5)/9)+1,"000")&"-2") | C8: =IF(OR(Registro_Compras!$C$4="",Registro_Compras!$O$4=""),"",IF(Registro_Compras!$AB$4="ADMINISTRATIVO","94","95")) | D8: =IF(OR(Registro_Compras!$C$4="",Registro_Compras!$O$4=""),"",IF(Registro_Compras!$AB$4="ADMINISTRATIVO","Gastos Administrativos","Gastos de Venta y Operacion")) | E8: =IF($C8="","",IF(Registro_Compras!$F$4="NOTA DE CREDITO","",IF(Registro_Compras!$F$4="RHE",ROUND(Registro_Compras!$L$4*Registro_Compras!$N$4,2),ROUND(Registro_Compras!$J$4*Registro_Compras!$N$4,2)))) | F8: =IF($C8="","",IF(Registro_Compras!$F$4="NOTA DE CREDITO",ROUND(ABS(Registro_Compras!$J$4*Registro_Compras!$N$4),2),"")) | G8: =IF($C8="","","Por el destino del gasto") | H8: =IF($C8="","",Registro_Compras!$C$4)
A9: =IF($C9="","",Registro_Compras!$B$4) | B9: =IF($C9="","","C"&TEXT(INT((ROW()-5)/9)+1,"000")&"-2") | C9: =IF(OR(Registro_Compras!$C$4="",Registro_Compras!$O$4=""),"","79/791") | D9: =IF(OR(Registro_Compras!$C$4="",Registro_Compras!$O$4=""),"","Cargas Imputables a Cuentas de Costos y Gastos") | E9: =IF($C9="","",IF(Registro_Compras!$F$4="NOTA DE CREDITO",ROUND(ABS(Registro_Compras!$J$4*Registro_Compras!$N$4),2),"")) | F9: =IF($C9="","",IF(Registro_Compras!$F$4="NOTA DE CREDITO","",IF(Registro_Compras!$F$4="RHE",ROUND(Registro_Compras!$L$4*Registro_Compras!$N$4,2),ROUND(Registro_Compras!$J$4*Registro_Compras!$N$4,2)))) | G9: =IF($C9="","","Por el destino del gasto") | H9: =IF($C9="","",Registro_Compras!$C$4)
A10: =IF($C10="","",Registro_Compras!$X$4) | B10: =IF($C10="","","C"&TEXT(INT((ROW()-5)/9)+1,"000")&"-3") | C10: =IF(OR(Registro_Compras!$C$4="",Registro_Compras!$O$4="",Registro_Compras!$R$4<>"SI",Registro_Compras!$X$4=""),"","4212") | D10: =IF(OR(Registro_Compras!$C$4="",Registro_Compras!$O$4=""),"","Cuentas por Pagar Comerciales - Terceros") | E10: =IF($C10="","",Registro_Compras!$S$4) | F10: ="" | G10: =IF($C10="","","Por el deposito de la detraccion en el Banco de la Nacion") | H10: =IF($C10="","",Registro_Compras!$C$4)
A11: =IF($C11="","",Registro_Compras!$X$4) | B11: =IF($C11="","","C"&TEXT(INT((ROW()-5)/9)+1,"000")&"-3") | C11: =IF(OR(Registro_Compras!$C$4="",Registro_Compras!$O$4="",Registro_Compras!$R$4<>"SI",Registro_Compras!$X$4=""),"","10413") | D11: =IF(OR(Registro_Compras!$C$4="",Registro_Compras!$O$4=""),"","Efectivo y Equivalentes - Cta. Cte. Operativa") | E11: ="" | F11: =IF($C11="","",Registro_Compras!$S$4) | G11: =IF($C11="","","Por el deposito de la detraccion en el Banco de la Nacion") | H11: =IF($C11="","",Registro_Compras!$C$4)
